Workbook

Sheet Indicadores
A1: ID | B1: Nome | C1: 2024 | K1: 2023 | S1: 2022 | AA1: 2021 | AI1: 2020
C2: Receita per capita | D2: Participação dos gastos operacionais | E2: Cobertura de despesas | F2: Recursos para cobertura de queda de receita | G2: Recursos para cobertura de obrigações correntes | H2: Compromentimento das receitas com as obrigações correntes | I2: Dívida per capita | J2: Comprometimento das receitas correntes com o endividamento | K2: Receita per capita | L2: Participação dos gastos operacionais | M2: Cobertura de despesas | N2: Recursos para cobertura de queda de receita | O2: Recursos para cobertura de obrigações correntes | P2: Compromentimento das receitas com as obrigações correntes | Q2: Dívida per capita | R2: Comprometimento das receitas correntes com o endividamento | S2: Receita per capita | T2: Participação dos gastos operacionais | U2: Cobertura de despesas | V2: Recursos para cobertura de queda de receita | W2: Recursos para cobertura de obrigações correntes | X2: Compromentimento das receitas com as obrigações correntes | Y2: Dívida per capita | Z2: Comprometimento das receitas correntes com o endividamento | AA2: Receita per capita | AB2: Participação dos gastos operacionais | AC2: Cobertura de despesas | AD2: Recursos para cobertura de queda de receita | AE2: Recursos para cobertura de obrigações correntes | AF2: Compromentimento das receitas com as obrigações correntes | AG2: Dívida per capita | AH2: Comprometimento das receitas correntes com o endividamento | AI2: Receita per capita | AJ2: Participação dos gastos operacionais | AK2: Cobertura de despesas | AL2: Recursos para cobertura de queda de receita | AM2: Recursos para cobertura de obrigações correntes | AN2: Compromentimento das receitas com as obrigações correntes | AO2: Dívida per capita | AP2: Comprometimento das receitas correntes com o endividamento
A3: 9 | B3: Consórcio Público da Região Polo Sul - CIM POLO SUL | C3: =Dados!F3/Dados!G3 -> 131.98121 | D3: =Dados!H3/Dados!I3 -> 0.99379144 | E3: =Dados!F3/Dados!I3 -> 1.0458449 | F3: =Dados!J3/Dados!F3 -> 0.043835287 | G3: =Dados!K3/Dados!M3 -> 4876.8989 | H3: =Dados!M3/Dados!F3 -> 2.9992424e-06 | I3: =Dados!N3/Dados!G3 -> 0 | J3: =Dados!N3/Dados!L3 -> 0 | K3: =Dados!O3/Dados!P3 -> 118.12805 | L3: =Dados!Q3/Dados!R3 -> 0.98602512 | M3: =Dados!O3/Dados!R3 -> 1.0012242 | N3: =Dados!S3/Dados!O3 -> 0.0012227107 | O3: =Dados!T3/Dados!V3 -> 145.02036 | P3: =Dados!V3/Dados!O3 -> 0.00067837287 | Q3: =Dados!W3/Dados!P3 -> 0 | R3: =Dados!W3/Dados!U3 -> 0 | S3: =Dados!X3/Dados!Y3 -> 88.942868 | T3: =Dados!Z3/Dados!AA3 -> 0.97864604 | U3: =Dados!X3/Dados!AA3 -> 1.0223186 | V3: =Dados!AB3/Dados!X3 -> 0.021831333 | W3: =Dados!AC3/Dados!AE3 -> 16.740434 | X3: =Dados!AE3/Dados!X3 -> 0.0076911137 | Y3: =Dados!AF3/Dados!Y3 -> 0 | Z3: =Dados!AF3/Dados!AD3 -> 0 | AA3: =Dados!AG3/Dados!AH3 -> 68.96868 | AB3: =Dados!AI3/Dados!AJ3 -> 0.99949881 | AC3: =Dados!AG3/Dados!AJ3 -> 1.0632336 | AD3: =Dados!AK3/Dados!AG3 -> 0.059472904 | AE3: =Dados!AL3/Dados!AN3 -> 258.86675 | AF3: =Dados!AN3/Dados!AG3 -> 0.00049883075 | AG3: =Dados!AO3/Dados!AH3 -> 0 | AH3: =Dados!AO3/Dados!AM3 -> 0 | AI3: =Dados!AP3/Dados!AQ3 -> 34.956594 | AJ3: =Dados!AR3/Dados!AS3 -> 0.99561601 | AK3: =Dados!AP3/Dados!AS3 -> 1.0691754 | AL3: =Dados!AT3/Dados!AP3 -> 0.06469975 | AM3: =Dados!AU3/Dados!AW3 -> 153.86168 | AN3: =Dados!AW3/Dados!AP3 -> 0.00089588769 | AO3: =Dados!AX3/Dados!AQ3 -> 0 | AP3: =Dados!AX3/Dados!AV3 -> 0
A4: 20 | B4: Consórcio Público Intermunicipal de Saúde do Alto Paranaíba - CISALP | C4: =Dados!F4/Dados!G4 -> 298.14327 | D4: =Dados!H4/Dados!I4 -> 0.95393904 | E4: =Dados!F4/Dados!I4 -> 1.0798705 | F4: =Dados!J4/Dados!F4 -> 0.073963013 | G4: =Dados!K4/Dados!M4 -> 61.770847 | H4: =Dados!M4/Dados!F4 -> 0.0048483245 | I4: =Dados!N4/Dados!G4 -> 0 | J4: =Dados!N4/Dados!L4 -> 0 | K4: =Dados!O4/Dados!P4 -> 192.56048 | L4: =Dados!Q4/Dados!R4 -> 0.98686509 | M4: =Dados!O4/Dados!R4 -> 1.1597657 | N4: =Dados!S4/Dados!O4 -> 0.13775689 | O4: =Dados!T4/Dados!V4 -> 24.202512 | P4: =Dados!V4/Dados!O4 -> 0.010297431 | Q4: =Dados!W4/Dados!P4 -> 0 | R4: =Dados!W4/Dados!U4 -> 0 | S4: =Dados!X4/Dados!Y4 -> 76.994652 | T4: =Dados!Z4/Dados!AA4 -> 0.99767172 | U4: =Dados!X4/Dados!AA4 -> 1.0936365 | V4: =Dados!AB4/Dados!X4 -> 0.085619375 | W4: =Dados!AC4/Dados!AE4 -> 55.53288 | X4: =Dados!AE4/Dados!X4 -> 0.0032764694 | Y4: =Dados!AF4/Dados!Y4 -> 0 | Z4: =Dados!AF4/Dados!AD4 -> 0 | AA4: =Dados!AG4/Dados!AH4 -> 30.96375 | AB4: =Dados!AI4/Dados!AJ4 -> 0.99410858 | AC4: =Dados!AG4/Dados!AJ4 -> 0.99688525 | AD4: =Dados!AK4/Dados!AG4 -> -0.0031244836 | AE4: =Dados!AL4/Dados!AN4 -> 4.4063119 | AF4: =Dados!AN4/Dados!AG4 -> 0.028615469 | AG4: =Dados!AO4/Dados!AH4 -> 0 | AH4: =Dados!AO4/Dados!AM4 -> 0 | AI4: =Dados!AP4/Dados!AQ4 -> 14.982399 | AJ4: =Dados!AR4/Dados!AS4 -> 0.99770234 | AK4: =Dados!AP4/Dados!AS4 -> 0.9623125 | AL4: =Dados!AT4/Dados!AP4 -> -0.039163478 | AM4: =Dados!AU4/Dados!AW4 -> 7.4026333 | AN4: =Dados!AW4/Dados!AP4 -> 0.013662892 | AO4: =Dados!AX4/Dados!AQ4 -> 0 | AP4: =Dados!AX4/Dados!AV4 -> 0
A5: 21 | B5: Consórcio Intermunicipal de Saúde da Mata Leste CISLESTE | C5: =Dados!F5/Dados!G5 -> 192.19075 | D5: =Dados!H5/Dados!I5 -> 0.94680416 | E5: =Dados!F5/Dados!I5 -> 1.0847602 | F5: =Dados!J5/Dados!F5 -> 0.078137228 | G5: =Dados!K5/Dados!M5 -> #DIV/0! | H5: =Dados!M5/Dados!F5 -> 0 | I5: =Dados!N5/Dados!G5 -> 0 | J5: =Dados!N5/Dados!L5 -> 0 | K5: =Dados!O5/Dados!P5 -> 144.36714 | L5: =Dados!Q5/Dados!R5 -> 0.99332918 | M5: =Dados!O5/Dados!R5 -> 1.142129 | N5: =Dados!S5/Dados!O5 -> 0.12444218 | O5: =Dados!T5/Dados!V5 -> #DIV/0! | P5: =Dados!V5/Dados!O5 -> 0 | Q5: =Dados!W5/Dados!P5 -> 0 | R5: =Dados!W5/Dados!U5 -> 0 | S5: =Dados!X5/Dados!Y5 -> 109.27206 | T5: =Dados!Z5/Dados!AA5 -> 0.99794734 | U5: =Dados!X5/Dados!AA5 -> 1.1075066 | V5: =Dados!AB5/Dados!X5 -> 0.097070841 | W5: =Dados!AC5/Dados!AE5 -> #DIV/0! | X5: =Dados!AE5/Dados!X5 -> 0 | Y5: =Dados!AF5/Dados!Y5 -> 0 | Z5: =Dados!AF5/Dados!AD5 -> 0 | AA5: =Dados!AG5/Dados!AH5 -> 71.91703 | AB5: =Dados!AI5/Dados!AJ5 -> 0.99105927 | AC5: =Dados!AG5/Dados!AJ5 -> 0.98457617 | AD5: =Dados!AK5/Dados!AG5 -> -0.015665447 | AE5: =Dados!AL5/Dados!AN5 -> #DIV/0! | AF5: =Dados!AN5/Dados!AG5 -> 0 | AG5: =Dados!AO5/Dados!AH5 -> 0 | AH5: =Dados!AO5/Dados!AM5 -> 0 | AI5: =Dados!AP5/Dados!AQ5 -> 46.537106 | AJ5: =Dados!AR5/Dados!AS5 -> 0.97749583 | AK5: =Dados!AP5/Dados!AS5 -> 0.97551813 | AL5: =Dados!AT5/Dados!AP5 -> -0.025096274 | AM5: =Dados!AU5/Dados!AW5 -> #DIV/0! | AN5: =Dados!AW5/Dados!AP5 -> 0 | AO5: =Dados!AX5/Dados!AQ5 -> 0 | AP5: =Dados!AX5/Dados!AV5 -> 0
A6: 28 | B6: Consórcio Intermunicipal de Saúde da Microrregião de Viçosa CISMIV | C6: =Dados!F6/Dados!G6 -> 149.17299 | D6: =Dados!H6/Dados!I6 -> 0.74115328 | E6: =Dados!F6/Dados!I6 -> 0.99155557 | F6: =Dados!J6/Dados!F6 -> -0.0085163423 | G6: =Dados!K6/Dados!M6 -> 294.43769 | H6: =Dados!M6/Dados!F6 -> 0.0015851836 | I6: =Dados!N6/Dados!G6 -> 0 | J6: =Dados!N6/Dados!L6 -> 0 | K6: =Dados!O6/Dados!P6 -> 121.54991 | L6: =Dados!Q6/Dados!R6 -> 0.86459488 | M6: =Dados!O6/Dados!R6 -> 1.3073137 | N6: =Dados!S6/Dados!O6 -> 0.23507266 | O6: =Dados!T6/Dados!V6 -> 40.287197 | P6: =Dados!V6/Dados!O6 -> 0.01466005 | Q6: =Dados!W6/Dados!P6 -> 0 | R6: =Dados!W6/Dados!U6 -> 0 | S6: =Dados!X6/Dados!Y6 -> 98.931082 | T6: =Dados!Z6/Dados!AA6 -> 0.96782592 | U6: =Dados!X6/Dados!AA6 -> 1.2282707 | V6: =Dados!AB6/Dados!X6 -> 0.18584725 | W6: =Dados!AC6/Dados!AE6 -> 15.745738 | X6: =Dados!AE6/Dados!X6 -> 0.022206006 | Y6: =Dados!AF6/Dados!Y6 -> 0 | Z6: =Dados!AF6/Dados!AD6 -> 0 | AA6: =Dados!AG6/Dados!AH6 -> 68.220395 | AB6: =Dados!AI6/Dados!AJ6 -> 0.99558674 | AC6: =Dados!AG6/Dados!AJ6 -> 1.0641193 | AD6: =Dados!AK6/Dados!AG6 -> 0.06025575 | AE6: =Dados!AL6/Dados!AN6 -> 6.6373693 | AF6: =Dados!AN6/Dados!AG6 -> 0.033210694 | AG6: =Dados!AO6/Dados!AH6 -> 0 | AH6: =Dados!AO6/Dados!AM6 -> 0 | AI6: =Dados!AP6/Dados!AQ6 -> 47.760847 | AJ6: =Dados!AR6/Dados!AS6 -> 0.97341422 | AK6: =Dados!AP6/Dados!AS6 -> 1.1436009 | AL6: =Dados!AT6/Dados!AP6 -> 0.11842353 | AM6: =Dados!AU6/Dados!AW6 -> 5.8236486 | AN6: =Dados!AW6/Dados!AP6 -> 0.041164439 | AO6: =Dados!AX6/Dados!AQ6 -> 0 | AP6: =Dados!AX6/Dados!AV6 -> 0
A7: 29 | B7: Consórcio Intermunicipal de Saúde do Alto das Vertentes - CISALV | C7: =Dados!F7/Dados!G7 -> 141.08762 | D7: =Dados!H7/Dados!I7 -> 0.9223693 | E7: =Dados!F7/Dados!I7 -> 1.4088142 | F7: =Dados!J7/Dados!F7 -> 0.2901832 | G7: =Dados!K7/Dados!M7 -> 46.497676 | H7: =Dados!M7/Dados!F7 -> 0.010215208 | I7: =Dados!N7/Dados!G7 -> 0 | J7: =Dados!N7/Dados!L7 -> 0 | K7: =Dados!O7/Dados!P7 -> 84.098522 | L7: =Dados!Q7/Dados!R7 -> 0.76632518 | M7: =Dados!O7/Dados!R7 -> 1.0892972 | N7: =Dados!S7/Dados!O7 -> 0.081976882 | O7: =Dados!T7/Dados!V7 -> 60.602593 | P7: =Dados!V7/Dados!O7 -> 0.006774024 | Q7: =Dados!W7/Dados!P7 -> 0 | R7: =Dados!W7/Dados!U7 -> 0 | S7: =Dados!X7/Dados!Y7 -> 62.810079 | T7: =Dados!Z7/Dados!AA7 -> 0.9798645 | U7: =Dados!X7/Dados!AA7 -> 1.3544978 | V7: =Dados!AB7/Dados!X7 -> 0.26171901 | W7: =Dados!AC7/Dados!AE7 -> 221.28946 | X7: =Dados!AE7/Dados!X7 -> 0.0013991096 | Y7: =Dados!AF7/Dados!Y7 -> 0 | Z7: =Dados!AF7/Dados!AD7 -> 0 | AA7: =Dados!AG7/Dados!AH7 -> 33.105997 | AB7: =Dados!AI7/Dados!AJ7 -> 0.98506872 | AC7: =Dados!AG7/Dados!AJ7 -> 1.0303373 | AD7: =Dados!AK7/Dados!AG7 -> 0.029444017 | AE7: =Dados!AL7/Dados!AN7 -> 226.29762 | AF7: =Dados!AN7/Dados!AG7 -> 0.0012052133 | AG7: =Dados!AO7/Dados!AH7 -> 0 | AH7: =Dados!AO7/Dados!AM7 -> 0 | AI7: =Dados!AP7/Dados!AQ7 -> 25.454376 | AJ7: =Dados!AR7/Dados!AS7 -> 0.98998414 | AK7: =Dados!AP7/Dados!AS7 -> 1.0417823 | AL7: =Dados!AT7/Dados!AP7 -> 0.040106592 | AM7: =Dados!AU7/Dados!AW7 -> 42.702597 | AN7: =Dados!AW7/Dados!AP7 -> 0.0032152328 | AO7: =Dados!AX7/Dados!AQ7 -> 0 | AP7: =Dados!AX7/Dados!AV7 -> 0
A8: 31 | B8: Consorcio Intermunicipal de Especialidades - CIESP | C8: =Dados!F8/Dados!G8 -> 113.84361 | D8: =Dados!H8/Dados!I8 -> 0.8088657 | E8: =Dados!F8/Dados!I8 -> 1.6741895 | F8: =Dados!J8/Dados!F8 -> 0.40269603 | G8: =Dados!K8/Dados!M8 -> 23.97661 | H8: =Dados!M8/Dados!F8 -> 0.021598212 | I8: =Dados!N8/Dados!G8 -> 0 | J8: =Dados!N8/Dados!L8 -> 0 | K8: =Dados!O8/Dados!P8 -> 81.067086 | L8: =Dados!Q8/Dados!R8 -> 0.7858529 | M8: =Dados!O8/Dados!R8 -> 1.5564725 | N8: =Dados!S8/Dados!O8 -> 0.35752156 | O8: =Dados!T8/Dados!V8 -> 23.743864 | P8: =Dados!V8/Dados!O8 -> 0.020880114 | Q8: =Dados!W8/Dados!P8 -> 0 | R8: =Dados!W8/Dados!U8 -> 0 | S8: =Dados!X8/Dados!Y8 -> 60.889554 | T8: =Dados!Z8/Dados!AA8 -> 0.9849943 | U8: =Dados!X8/Dados!AA8 -> 1.4709891 | V8: =Dados!AB8/Dados!X8 -> 0.32018529 | W8: =Dados!AC8/Dados!AE8 -> 29.416035 | X8: =Dados!AE8/Dados!X8 -> 0.013077873 | Y8: =Dados!AF8/Dados!Y8 -> 0 | Z8: =Dados!AF8/Dados!AD8 -> 0 | AA8: =Dados!AG8/Dados!AH8 -> 37.591366 | AB8: =Dados!AI8/Dados!AJ8 -> 0.99247945 | AC8: =Dados!AG8/Dados!AJ8 -> 1.1372946 | AD8: =Dados!AK8/Dados!AG8 -> 0.12072034 | AE8: =Dados!AL8/Dados!AN8 -> 3.582357 | AF8: =Dados!AN8/Dados!AG8 -> 0.093652921 | AG8: =Dados!AO8/Dados!AH8 -> 0 | AH8: =Dados!AO8/Dados!AM8 -> 0 | AI8: =Dados!AP8/Dados!AQ8 -> 28.357114 | AJ8: =Dados!AR8/Dados!AS8 -> 0.98605302 | AK8: =Dados!AP8/Dados!AS8 -> 1.0588013 | AL8: =Dados!AT8/Dados!AP8 -> 0.055535747 | AM8: =Dados!AU8/Dados!AW8 -> 3.2915997 | AN8: =Dados!AW8/Dados!AP8 -> 0.10685843 | AO8: =Dados!AX8/Dados!AQ8 -> 0 | AP8: =Dados!AX8/Dados!AV8 -> 0
A9: 33 | B9: Consórcio Público Intermunicipal de Saúde do Triângulo Mineiro CISTM | C9: =Dados!F9/Dados!G9 -> 0 | D9: =Dados!H9/Dados!I9 -> #DIV/0! | E9: =Dados!F9/Dados!I9 -> #DIV/0! | F9: =Dados!J9/Dados!F9 -> #DIV/0! | G9: =Dados!K9/Dados!M9 -> #DIV/0! | H9: =Dados!M9/Dados!F9 -> #DIV/0! | I9: =Dados!N9/Dados!G9 -> 0 | J9: =Dados!N9/Dados!L9 -> #DIV/0! | K9: =Dados!O9/Dados!P9 -> 0 | L9: =Dados!Q9/Dados!R9 -> #DIV/0! | M9: =Dados!O9/Dados!R9 -> #DIV/0! | N9: =Dados!S9/Dados!O9 -> #DIV/0! | O9: =Dados!T9/Dados!V9 -> #DIV/0! | P9: =Dados!V9/Dados!O9 -> #DIV/0! | Q9: =Dados!W9/Dados!P9 -> 0 | R9: =Dados!W9/Dados!U9 -> #DIV/0! | S9: =Dados!X9/Dados!Y9 -> 0 | T9: =Dados!Z9/Dados!AA9 -> #DIV/0! | U9: =Dados!X9/Dados!AA9 -> #DIV/0! | V9: =Dados!AB9/Dados!X9 -> #DIV/0! | W9: =Dados!AC9/Dados!AE9 -> #DIV/0! | X9: =Dados!AE9/Dados!X9 -> #DIV/0! | Y9: =Dados!AF9/Dados!Y9 -> 0 | Z9: =Dados!AF9/Dados!AD9 -> #DIV/0! | AA9: =Dados!AG9/Dados!AH9 -> 19.347946 | AB9: =Dados!AI9/Dados!AJ9 -> 0.9646851 | AC9: =Dados!AG9/Dados!AJ9 -> 0.98531075 | AD9: =Dados!AK9/Dados!AG9 -> -0.014908237 | AE9: =Dados!AL9/Dados!AN9 -> 134.20373 | AF9: =Dados!AN9/Dados!AG9 -> 0.0023500074 | AG9: =Dados!AO9/Dados!AH9 -> 0 | AH9: =Dados!AO9/Dados!AM9 -> 0 | AI9: =Dados!AP9/Dados!AQ9 -> 16.01279 | AJ9: =Dados!AR9/Dados!AS9 -> 0.96270633 | AK9: =Dados!AP9/Dados!AS9 -> 1.121282 | AL9: =Dados!AT9/Dados!AP9 -> 0.10816372 | AM9: =Dados!AU9/Dados!AW9 -> 26.740109 | AN9: =Dados!AW9/Dados!AP9 -> 0.013626377 | AO9: =Dados!AX9/Dados!AQ9 -> 0 | AP9: =Dados!AX9/Dados!AV9 -> 0
A10: 36 | B10: Consórcio Intermunicipal de Saúde da Rede de Urgência e Emergência da Região Ampliada do Noroeste CISREUNO | C10: =Dados!F10/Dados!G10 -> 61.134074 | D10: =Dados!H10/Dados!I10 -> 0.97218914 | E10: =Dados!F10/Dados!I10 -> 0.95479087 | F10: =Dados!J10/Dados!F10 -> -0.047349767 | G10: =Dados!K10/Dados!M10 -> 12.417569 | H10: =Dados!M10/Dados!F10 -> 0.039151113 | I10: =Dados!N10/Dados!G10 -> 0 | J10: =Dados!N10/Dados!L10 -> 0 | K10: =Dados!O10/Dados!P10 -> 59.471803 | L10: =Dados!Q10/Dados!R10 -> 0.98452569 | M10: =Dados!O10/Dados!R10 -> 1.1374787 | N10: =Dados!S10/Dados!O10 -> 0.12086263 | O10: =Dados!T10/Dados!V10 -> 73.579807 | P10: =Dados!V10/Dados!O10 -> 0.0070071869 | Q10: =Dados!W10/Dados!P10 -> 0 | R10: =Dados!W10/Dados!U10 -> 0 | S10: =Dados!X10/Dados!Y10 -> 11.529927 | T10: =Dados!Z10/Dados!AA10 -> 0.32061169 | U10: =Dados!X10/Dados!AA10 -> 0.45311475 | V10: =Dados!AB10/Dados!X10 -> -1.2069465 | W10: =Dados!AC10/Dados!AE10 -> 634.25152 | X10: =Dados!AE10/Dados!X10 -> 0.0025232998 | Y10: =Dados!AF10/Dados!Y10 -> 0 | Z10: =Dados!AF10/Dados!AD10 -> 0 | AA10: =Dados!AG10/Dados!AH10 -> 0 | AB10: =Dados!AI10/Dados!AJ10 -> #DIV/0! | AC10: =Dados!AG10/Dados!AJ10 -> #DIV/0! | AD10: =Dados!AK10/Dados!AG10 -> #DIV/0! | AE10: =Dados!AL10/Dados!AN10 -> 10549.048 | AF10: =Dados!AN10/Dados!AG10 -> #DIV/0! | AG10: =Dados!AO10/Dados!AH10 -> 0 | AH10: =Dados!AO10/Dados!AM10 -> #DIV/0! | AI10: =Dados!AP10/Dados!AQ10 -> 0 | AJ10: =Dados!AR10/Dados!AS10 -> #DIV/0! | AK10: =Dados!AP10/Dados!AS10 -> #DIV/0! | AL10: =Dados!AT10/Dados!AP10 -> #DIV/0! | AM10: =Dados!AU10/Dados!AW10 -> #DIV/0! | AN10: =Dados!AW10/Dados!AP10 -> #DIV/0! | AO10: =Dados!AX10/Dados!AQ10 -> 0 | AP10: =Dados!AX10/Dados!AV10 -> #DIV/0!
A11: 37 | B11: Consórcio Intermunicipal Multifinalitário do Vale de Paraibuna - CIMPAR | C11: =Dados!F11/Dados!G11 -> 19.787759 | D11: =Dados!H11/Dados!I11 -> 1 | E11: =Dados!F11/Dados!I11 -> 0.97959103 | F11: =Dados!J11/Dados!F11 -> -0.020834178 | G11: =Dados!K11/Dados!M11 -> 6.0059356 | H11: =Dados!M11/Dados!F11 -> 0.020442819 | I11: =Dados!N11/Dados!G11 -> 0 | J11: =Dados!N11/Dados!L11 -> 0 | K11: =Dados!O11/Dados!P11 -> 15.653826 | L11: =Dados!Q11/Dados!R11 -> 0.9974628 | M11: =Dados!O11/Dados!R11 -> 1.0476682 | N11: =Dados!S11/Dados!O11 -> 0.045499366 | O11: =Dados!T11/Dados!V11 -> 1.6183073 | P11: =Dados!V11/Dados!O11 -> 0.096841777 | Q11: =Dados!W11/Dados!P11 -> 0 | R11: =Dados!W11/Dados!U11 -> 0 | S11: =Dados!X11/Dados!Y11 -> 0 | T11: =Dados!Z11/Dados!AA11 -> #DIV/0! | U11: =Dados!X11/Dados!AA11 -> #DIV/0! | V11: =Dados!AB11/Dados!X11 -> #DIV/0! | W11: =Dados!AC11/Dados!AE11 -> #DIV/0! | X11: =Dados!AE11/Dados!X11 -> #DIV/0! | Y11: =Dados!AF11/Dados!Y11 -> 0 | Z11: =Dados!AF11/Dados!AD11 -> #DIV/0! | AA11: =Dados!AG11/Dados!AH11 -> 0 | AB11: =Dados!AI11/Dados!AJ11 -> #DIV/0! | AC11: =Dados!AG11/Dados!AJ11 -> #DIV/0! | AD11: =Dados!AK11/Dados!AG11 -> #DIV/0! | AE11: =Dados!AL11/Dados!AN11 -> #DIV/0! | AF11: =Dados!AN11/Dados!AG11 -> #DIV/0! | AG11: =Dados!AO11/Dados!AH11 -> 0 | AH11: =Dados!AO11/Dados!AM11 -> #DIV/0! | AI11: =Dados!AP11/Dados!AQ11 -> 0 | AJ11: =Dados!AR11/Dados!AS11 -> #DIV/0! | AK11: =Dados!AP11/Dados!AS11 -> #DIV/0! | AL11: =Dados!AT11/Dados!AP11 -> #DIV/0! | AM11: =Dados!AU11/Dados!AW11 -> #DIV/0! | AN11: =Dados!AW11/Dados!AP11 -> #DIV/0! | AO11: =Dados!AX11/Dados!AQ11 -> 0 | AP11: =Dados!AX11/Dados!AV11 -> #DIV/0!
A12: 39 | B12: Consórcio Intermunicipal de Saúde do Médio Espinhaço CISAME | C12: =Dados!F12/Dados!G12 -> 123.45463 | D12: =Dados!H12/Dados!I12 -> 0.79776564 | E12: =Dados!F12/Dados!I12 -> 2.4677845 | F12: =Dados!J12/Dados!F12 -> 0.59477823 | G12: =Dados!K12/Dados!M12 -> 42.179628 | H12: =Dados!M12/Dados!F12 -> 0.016695941 | I12: =Dados!N12/Dados!G12 -> 0 | J12: =Dados!N12/Dados!L12 -> 0 | K12: =Dados!O12/Dados!P12 -> 38.496369 | L12: =Dados!Q12/Dados!R12 -> 0.98399692 | M12: =Dados!O12/Dados!R12 -> 0.71464137 | N12: =Dados!S12/Dados!O12 -> -0.39930326 | O12: =Dados!T12/Dados!V12 -> 1.7945236 | P12: =Dados!V12/Dados!O12 -> 0.057917431 | Q12: =Dados!W12/Dados!P12 -> 0 | R12: =Dados!W12/Dados!U12 -> 0 | S12: =Dados!X12/Dados!Y12 -> 45.151685 | T12: =Dados!Z12/Dados!AA12 -> 1 | U12: =Dados!X12/Dados!AA12 -> 1.1475783 | V12: =Dados!AB12/Dados!X12 -> 0.12859978 | W12: =Dados!AC12/Dados!AE12 -> 16.118241 | X12: =Dados!AE12/Dados!X12 -> 0.032483966 | Y12: =Dados!AF12/Dados!Y12 -> 0 | Z12: =Dados!AF12/Dados!AD12 -> 0 | AA12: =Dados!AG12/Dados!AH12 -> 0 | AB12: =Dados!AI12/Dados!AJ12 -> #DIV/0! | AC12: =Dados!AG12/Dados!AJ12 -> #DIV/0! | AD12: =Dados!AK12/Dados!AG12 -> #DIV/0! | AE12: =Dados!AL12/Dados!AN12 -> #DIV/0! | AF12: =Dados!AN12/Dados!AG12 -> #DIV/0! | AG12: =Dados!AO12/Dados!AH12 -> 0 | AH12: =Dados!AO12/Dados!AM12 -> #DIV/0! | AI12: =Dados!AP12/Dados!AQ12 -> 0 | AJ12: =Dados!AR12/Dados!AS12 -> #DIV/0! | AK12: =Dados!AP12/Dados!AS12 -> #DIV/0! | AL12: =Dados!AT12/Dados!AP12 -> #DIV/0! | AM12: =Dados!AU12/Dados!AW12 -> #DIV/0! | AN12: =Dados!AW12/Dados!AP12 -> #DIV/0! | AO12: =Dados!AX12/Dados!AQ12 -> 0 | AP12: =Dados!AX12/Dados!AV12 -> #DIV/0!
A13: 41 | B13: Consórcio Intermunicipal de Saúde do Sistema Microrregional de Saúde de São Lourenço Cis Circuito das Águas | C13: =Dados!F13/Dados!G13 -> 412.47529 | D13: =Dados!H13/Dados!I13 -> 0.92680335 | E13: =Dados!F13/Dados!I13 -> 1.1939181 | F13: =Dados!J13/Dados!F13 -> 0.1624216 | G13: =Dados!K13/Dados!M13 -> 6.1431975 | H13: =Dados!M13/Dados!F13 -> 0.032326429 | I13: =Dados!N13/Dados!G13 -> 0 | J13: =Dados!N13/Dados!L13 -> 0 | K13: =Dados!O13/Dados!P13 -> 231.45549 | L13: =Dados!Q13/Dados!R13 -> 0.98612613 | M13: =Dados!O13/Dados!R13 -> 1.0744025 | N13: =Dados!S13/Dados!O13 -> 0.069250096 | O13: =Dados!T13/Dados!V13 -> 4.157465 | P13: =Dados!V13/Dados!O13 -> 0.015819072 | Q13: =Dados!W13/Dados!P13 -> 0.530392 | R13: =Dados!W13/Dados!U13 -> 0.0024598947 | S13: =Dados!X13/Dados!Y13 -> 185.84369 | T13: =Dados!Z13/Dados!AA13 -> 0.99899017 | U13: =Dados!X13/Dados!AA13 -> 1.0246988 | V13: =Dados!AB13/Dados!X13 -> 0.024103442 | W13: =Dados!AC13/Dados!AE13 -> 0.78701704 | X13: =Dados!AE13/Dados!X13 -> 0.018388819 | Y13: =Dados!AF13/Dados!Y13 -> 0.306508 | Z13: =Dados!AF13/Dados!AD13 -> 0.0016554342 | AA13: =Dados!AG13/Dados!AH13 -> 138.69522 | AB13: =Dados!AI13/Dados!AJ13 -> 0.99632332 | AC13: =Dados!AG13/Dados!AJ13 -> 1.0123366 | AD13: =Dados!AK13/Dados!AG13 -> 0.012186263 | AE13: =Dados!AL13/Dados!AN13 -> 0.50656635 | AF13: =Dados!AN13/Dados!AG13 -> 0.025421543 | AG13: =Dados!AO13/Dados!AH13 -> 0.17247887 | AH13: =Dados!AO13/Dados!AM13 -> 0.0012444156 | AI13: =Dados!AP13/Dados!AQ13 -> 143.21339 | AJ13: =Dados!AR13/Dados!AS13 -> 0.99591495 | AK13: =Dados!AP13/Dados!AS13 -> 1.0406775 | AL13: =Dados!AT13/Dados!AP13 -> 0.039087513 | AM13: =Dados!AU13/Dados!AW13 -> 4.0353105 | AN13: =Dados!AW13/Dados!AP13 -> 0.012740122 | AO13: =Dados!AX13/Dados!AQ13 -> 0.5907435 | AP13: =Dados!AX13/Dados!AV13 -> 0.0041249182
A14: 53 | B14: Consórcio Intermunicipal de Desenvolvimento da Região Leste Fluminense - CONLESTE | C14: =Dados!F14/Dados!G14 -> 0.29722135 | D14: =Dados!H14/Dados!I14 -> 0.90257792 | E14: =Dados!F14/Dados!I14 -> 0.88779129 | F14: =Dados!J14/Dados!F14 -> -0.12639087 | G14: =Dados!K14/Dados!M14 -> 3.4187612 | H14: =Dados!M14/Dados!F14 -> 0.028715113 | I14: =Dados!N14/Dados!G14 -> 0.027191403 | J14: =Dados!N14/Dados!L14 -> 0.091485365 | K14: =Dados!O14/Dados!P14 -> 0.34843856 | L14: =Dados!Q14/Dados!R14 -> 0.88714441 | M14: =Dados!O14/Dados!R14 -> 1.0963676 | N14: =Dados!S14/Dados!O14 -> 0.087897141 | O14: =Dados!T14/Dados!V14 -> 7.0576662 | P14: =Dados!V14/Dados!O14 -> 0.027313964 | Q14: =Dados!W14/Dados!P14 -> 0.050445024 | R14: =Dados!W14/Dados!U14 -> 0.14477452 | S14: =Dados!X14/Dados!Y14 -> 0.272956 | T14: =Dados!Z14/Dados!AA14 -> 0.88969793 | U14: =Dados!X14/Dados!AA14 -> 0.86471058 | V14: =Dados!AB14/Dados!X14 -> -0.1564563 | W14: =Dados!AC14/Dados!AE14 -> 60.731619 | X14: =Dados!AE14/Dados!X14 -> 0.0020593399 | Y14: =Dados!AF14/Dados!Y14 -> 0.05544417 | Z14: =Dados!AF14/Dados!AD14 -> 0.20312493 | AA14: =Dados!AG14/Dados!AH14 -> 0.30807154 | AB14: =Dados!AI14/Dados!AJ14 -> 0.94411051 | AC14: =Dados!AG14/Dados!AJ14 -> 1.1424518 | AD14: =Dados!AK14/Dados!AG14 -> 0.12468953 | AE14: =Dados!AL14/Dados!AN14 -> 2.1196335 | AF14: =Dados!AN14/Dados!AG14 -> 0.1313013 | AG14: =Dados!AO14/Dados!AH14 -> 0.057516882 | AH14: =Dados!AO14/Dados!AM14 -> 0.18669976 | AI14: =Dados!AP14/Dados!AQ14 -> 0.21964176 | AJ14: =Dados!AR14/Dados!AS14 -> 0.97805807 | AK14: =Dados!AP14/Dados!AS14 -> 0.8781118 | AL14: =Dados!AT14/Dados!AP14 -> -0.13880715 | AM14: =Dados!AU14/Dados!AW14 -> 0.15552767 | AN14: =Dados!AW14/Dados!AP14 -> 0.34262326 | AO14: =Dados!AX14/Dados!AQ14 -> 0.023179883 | AP14: =Dados!AX14/Dados!AV14 -> 0.10553495
... A31: 172 | B31: Consórcio Intermunicipal de Saúde Verde - CISVERDE | C31: =Dados!F31/Dados!G31 -> 92.000696 | D31: =Dados!H31/Dados!I31 -> 0.74123679 | E31: =Dados!F31/Dados!I31 -> 1.0259376 | F31: =Dados!J31/Dados!F31 -> 0.025281816 | G31: =Dados!K31/Dados!M31 -> 4.6927901 | H31: =Dados!M31/Dados!F31 -> 0.092646134 | I31: =Dados!N31/Dados!G31 -> 0 | J31: =Dados!N31/Dados!L31 -> 0 | K31: =Dados!O31/Dados!P31 -> 76.151179 | L31: =Dados!Q31/Dados!R31 -> 1 | M31: =Dados!O31/Dados!R31 -> 1.5349145 | N31: =Dados!S31/Dados!O31 -> 0.34849792 | O31: =Dados!T31/Dados!V31 -> 9.8843316 | P31: =Dados!V31/Dados!O31 -> 0.042376922 | Q31: =Dados!W31/Dados!P31 -> 0 | R31: =Dados!W31/Dados!U31 -> 0 | S31: =Dados!X31/Dados!Y31 -> 34.128627 | T31: =Dados!Z31/Dados!AA31 -> 0.99326002 | U31: =Dados!X31/Dados!AA31 -> 0.99495304 | V31: =Dados!AB31/Dados!X31 -> -0.0050725643 | W31: =Dados!AC31/Dados!AE31 -> 2.8597262 | X31: =Dados!AE31/Dados!X31 -> 0.028584783 | Y31: =Dados!AF31/Dados!Y31 -> 0 | Z31: =Dados!AF31/Dados!AD31 -> 0 | AA31: =Dados!AG31/Dados!AH31 -> 25.261352 | AB31: =Dados!AI31/Dados!AJ31 -> 1 | AC31: =Dados!AG31/Dados!AJ31 -> 1.0195045 | AD31: =Dados!AK31/Dados!AG31 -> 0.01913138 | AE31: =Dados!AL31/Dados!AN31 -> 2.3924769 | AF31: =Dados!AN31/Dados!AG31 -> 0.050323125 | AG31: =Dados!AO31/Dados!AH31 -> 0 | AH31: =Dados!AO31/Dados!AM31 -> 0 | AI31: =Dados!AP31/Dados!AQ31 -> 19.957968 | AJ31: =Dados!AR31/Dados!AS31 -> 1 | AK31: =Dados!AP31/Dados!AS31 -> 1.1122712 | AL31: =Dados!AT31/Dados!AP31 -> 0.1009387 | AM31: =Dados!AU31/Dados!AW31 -> 3.5620962 | AN31: =Dados!AW31/Dados!AP31 -> 0.022335244 | AO31: =Dados!AX31/Dados!AQ31 -> 0 | AP31: =Dados!AX31/Dados!AV31 -> 0
A32: 176 | B32: Consórcio Intermunicipal de Desenvolvimento Economico e Social dos Municipios do Leste de Minas - CIDES-LESTE | C32: =Dados!F32/Dados!G32 -> 128.63067 | D32: =Dados!H32/Dados!I32 -> 0.84690782 | E32: =Dados!F32/Dados!I32 -> 1.317925 | F32: =Dados!J32/Dados!F32 -> 0.2412315 | G32: =Dados!K32/Dados!M32 -> 208.00623 | H32: =Dados!M32/Dados!F32 -> 0.0018775937 | I32: =Dados!N32/Dados!G32 -> 0 | J32: =Dados!N32/Dados!L32 -> 0 | K32: =Dados!#REF!/Dados!#REF! -> #REF! | L32: =Dados!Q32/Dados!R32 -> 0.69648088 | M32: =Dados!O32/Dados!R32 -> 0.96731008 | N32: =Dados!#REF!/Dados!#REF! -> #REF! | O32: =Dados!#REF!/Dados!#REF! -> #REF! | P32: =Dados!V32/Dados!O32 -> 0.033544546 | Q32: =Dados!#REF!/Dados!#REF! -> #REF! | R32: =Dados!#REF!/Dados!#REF! -> #REF! | S32: =Dados!#REF!/Dados!#REF! -> #REF! | T32: =Dados!Z32/Dados!AA32 -> 0.99902739 | U32: =Dados!X32/Dados!AA32 -> 1.3116678 | V32: =Dados!#REF!/Dados!#REF! -> #REF! | W32: =Dados!#REF!/Dados!#REF! -> #REF! | X32: =Dados!AE32/Dados!X32 -> 0.0004591948 | Y32: =Dados!#REF!/Dados!#REF! -> #REF! | Z32: =Dados!#REF!/Dados!#REF! -> #REF! | AA32: =Dados!#REF!/Dados!#REF! -> #REF! | AB32: =Dados!AI32/Dados!AJ32 -> 0.98691967 | AC32: =Dados!AG32/Dados!AJ32 -> 1.1092902 | AD32: =Dados!#REF!/Dados!#REF! -> #REF! | AE32: =Dados!#REF!/Dados!#REF! -> #REF! | AF32: =Dados!AN32/Dados!AG32 -> 0.0043454791 | AG32: =Dados!#REF!/Dados!#REF! -> #REF! | AH32: =Dados!#REF!/Dados!#REF! -> #REF! | AI32: =Dados!#REF!/Dados!#REF! -> #REF! | AJ32: =Dados!AR32/Dados!AS32 -> 0.9567385 | AK32: =Dados!AP32/Dados!AS32 -> 1.143657 | AL32: =Dados!#REF!/Dados!#REF! -> #REF! | AM32: =Dados!#REF!/Dados!#REF! -> #REF! | AN32: =Dados!AW32/Dados!AP32 -> 0.035913729 | AO32: =Dados!#REF!/Dados!#REF! -> #REF! | AP32: =Dados!#REF!/Dados!#REF! -> #REF!
A33: 181 | B33: Consórcio Intermunicipal de Saúde dos Municípios da Microrregião do Alto Sapucaí - CISMAS | C33: =Dados!F33/Dados!G33 -> 394.02165 | D33: =Dados!H33/Dados!I33 -> 0.89672252 | E33: =Dados!F33/Dados!I33 -> 1.4158462 | F33: =Dados!J33/Dados!F33 -> 0.29370861 | G33: =Dados!K33/Dados!M33 -> 26.920483 | H33: =Dados!M33/Dados!F33 -> 0.016196603 | I33: =Dados!N33/Dados!G33 -> 0 | J33: =Dados!N33/Dados!L33 -> 0 | K33: =Dados!O32/Dados!P32 -> 88.63164 | L33: =Dados!Q33/Dados!R33 -> 0.89004508 | M33: =Dados!O33/Dados!R33 -> 1.1074334 | N33: =Dados!S32/Dados!O32 -> -0.033794661 | O33: =Dados!T32/Dados!V32 -> 14.587907 | P33: =Dados!V33/Dados!O33 -> 0.03075476 | Q33: =Dados!W32/Dados!P32 -> 0 | R33: =Dados!W32/Dados!U32 -> 0 | S33: =Dados!X32/Dados!Y32 -> 60.654414 | T33: =Dados!Z33/Dados!AA33 -> 0.96240035 | U33: =Dados!X33/Dados!AA33 -> 1.2125858 | V33: =Dados!AB32/Dados!X32 -> 0.23761183 | W33: =Dados!AC32/Dados!AE32 -> 776.81886 | X33: =Dados!AE33/Dados!X33 -> 0.065713013 | Y33: =Dados!AF32/Dados!Y32 -> 0 | Z33: =Dados!AF32/Dados!AD32 -> 0 | AA33: =Dados!AG32/Dados!AH32 -> 35.716226 | AB33: =Dados!AI33/Dados!AJ33 -> 0.86692349 | AC33: =Dados!AG33/Dados!AJ33 -> 1.5049172 | AD33: =Dados!AK32/Dados!AG32 -> 0.098522612 | AE33: =Dados!AL32/Dados!AN32 -> 48.746383 | AF33: =Dados!AN33/Dados!AG33 -> 0.038315186 | AG33: =Dados!AO32/Dados!AH32 -> 0 | AH33: =Dados!AO32/Dados!AM32 -> 0 | AI33: =Dados!AP32/Dados!AQ32 -> 25.96374 | AJ33: =Dados!AR33/Dados!AS33 -> 0.96078554 | AK33: =Dados!AP33/Dados!AS33 -> 1.2680474 | AL33: =Dados!AT32/Dados!AP32 -> 0.12561193 | AM33: =Dados!AU32/Dados!AW32 -> 5.2389226 | AN33: =Dados!AW33/Dados!AP33 -> 0.050449252 | AO33: =Dados!AX32/Dados!AQ32 -> 0 | AP33: =Dados!AX32/Dados!AV32 -> 0
A34: 183 | B34: Agência de Cooperação Intermunicipal em Saúde Pé da Serra - ACISPES | C34: =Dados!F34/Dados!G34 -> 62.117001 | D34: =Dados!H34/Dados!I34 -> 0.9998747 | E34: =Dados!F34/Dados!I34 -> 1.0449942 | F34: =Dados!J34/Dados!F34 -> 0.043056852 | G34: =Dados!K34/Dados!M34 -> #DIV/0! | H34: =Dados!M34/Dados!F34 -> 0 | I34: =Dados!N34/Dados!G34 -> 0 | J34: =Dados!N34/Dados!L34 -> 0 | K34: =Dados!O33/Dados!P33 -> 263.18835 | L34: =Dados!Q34/Dados!R34 -> 0.99960487 | M34: =Dados!O34/Dados!R34 -> 0.9093874 | N34: =Dados!S33/Dados!O33 -> 0.097011139 | O34: =Dados!T33/Dados!V33 -> 13.482101 | P34: =Dados!V34/Dados!O34 -> 0 | Q34: =Dados!W33/Dados!P33 -> 0 | R34: =Dados!W33/Dados!U33 -> 0 | S34: =Dados!X33/Dados!Y33 -> 253.17485 | T34: =Dados!Z34/Dados!AA34 -> 0.9995956 | U34: =Dados!X34/Dados!AA34 -> 1.0848688 | V34: =Dados!AB33/Dados!X33 -> 0.1753161 | W34: =Dados!AC33/Dados!AE33 -> 6.4531772 | X34: =Dados!AE34/Dados!X34 -> 0 | Y34: =Dados!AF33/Dados!Y33 -> 0 | Z34: =Dados!AF33/Dados!AD33 -> 0 | AA34: =Dados!AG33/Dados!AH33 -> 246.39711 | AB34: =Dados!AI34/Dados!AJ34 -> #DIV/0! | AC34: =Dados!AG34/Dados!AJ34 -> #DIV/0! | AD34: =Dados!AK33/Dados!AG33 -> 0.33551164 | AE34: =Dados!AL33/Dados!AN33 -> 11.211187 | AF34: =Dados!AN34/Dados!AG34 -> #DIV/0! | AG34: =Dados!AO33/Dados!AH33 -> 0 | AH34: =Dados!AO33/Dados!AM33 -> 0 | AI34: =Dados!AP33/Dados!AQ33 -> 152.28863 | AJ34: =Dados!AR34/Dados!AS34 -> #DIV/0! | AK34: =Dados!AP34/Dados!AS34 -> #DIV/0! | AL34: =Dados!AT33/Dados!AP33 -> 0.21138595 | AM34: =Dados!AU33/Dados!AW33 -> 2.5377474 | AN34: =Dados!AW34/Dados!AP34 -> #DIV/0! | AO34: =Dados!AX33/Dados!AQ33 -> 0 | AP34: =Dados!AX33/Dados!AV33 -> 0
A35: 234 | B35: Consórcio Público Intermunicipal de Saúde do Norte e Noroeste Fluminense - CISNOVO | C35: =Dados!F35/Dados!G35 -> 14.273871 | D35: =Dados!H35/Dados!I35 -> 0.99729691 | E35: =Dados!F35/Dados!I35 -> 1.008187 | F35: =Dados!J35/Dados!F35 -> 0.0081204941 | G35: =Dados!K35/Dados!M35 -> 2.3733865 | H35: =Dados!M35/Dados!F35 -> 0.014771113 | I35: =Dados!N35/Dados!G35 -> 0.022172527 | J35: =Dados!N35/Dados!L35 -> 0.0015533647 | K35: =Dados!O34/Dados!P34 -> 49.64261 | L35: =Dados!Q35/Dados!R35 -> 0.98980862 | M35: =Dados!O35/Dados!R35 -> 0.75552354 | N35: =Dados!S34/Dados!O34 -> -0.099641364 | O35: =Dados!T34/Dados!V34 -> #DIV/0! | P35: =Dados!V35/Dados!O35 -> 0.044553035 | Q35: =Dados!W34/Dados!P34 -> 0 | R35: =Dados!W34/Dados!U34 -> 0 | S35: =Dados!X34/Dados!Y34 -> 46.933522 | T35: =Dados!Z35/Dados!AA35 -> 0.99116973 | U35: =Dados!X35/Dados!AA35 -> 0.90139933 | V35: =Dados!AB34/Dados!X34 -> 0.078229541 | W35: =Dados!AC34/Dados!AE34 -> #DIV/0! | X35: =Dados!AE35/Dados!X35 -> 0.094074041 | Y35: =Dados!AF34/Dados!Y34 -> 0 | Z35: =Dados!AF34/Dados!AD34 -> 0 | AA35: =Dados!AG34/Dados!AH34 -> 0 | AB35: =Dados!AI35/Dados!AJ35 -> 1 | AC35: =Dados!AG35/Dados!AJ35 -> 6.8980723 | AD35: =Dados!AK34/Dados!AG34 -> #DIV/0! | AE35: =Dados!AL34/Dados!AN34 -> #DIV/0! | AF35: =Dados!AN35/Dados!AG35 -> 0.077182049 | AG35: =Dados!AO34/Dados!AH34 -> 0 | AH35: =Dados!AO34/Dados!AM34 -> #DIV/0! | AI35: =Dados!AP34/Dados!AQ34 -> 0 | AJ35: =Dados!AR35/Dados!AS35 -> 0.97646157 | AK35: =Dados!AP35/Dados!AS35 -> 1 | AL35: =Dados!AT34/Dados!AP34 -> #DIV/0! | AM35: =Dados!AU34/Dados!AW34 -> #DIV/0! | AN35: =Dados!AW35/Dados!AP35 -> 0.16468894 | AO35: =Dados!AX34/Dados!AQ34 -> 0 | AP35: =Dados!AX34/Dados!AV34 -> #DIV/0!
A36: 236 | B36: Consórcio Intermunicipal de Saúde da Região Serrana - CIS-SERRA | C36: =Dados!F36/Dados!G36 -> 267.73442 | D36: =Dados!H36/Dados!I36 -> 0.9882184 | E36: =Dados!F36/Dados!I36 -> 0.95191701 | F36: =Dados!J36/Dados!F36 -> -0.050511741 | G36: =Dados!K36/Dados!M36 -> 0.073529327 | H36: =Dados!M36/Dados!F36 -> 0.073452838 | I36: =Dados!N36/Dados!G36 -> 0 | J36: =Dados!N36/Dados!L36 -> 0 | K36: =Dados!O35/Dados!P35 -> 2.1170133 | L36: =Dados!Q36/Dados!R36 -> 0.99798257 | M36: =Dados!O36/Dados!R36 -> 0.98483214 | N36: =Dados!S35/Dados!O35 -> -0.32358551 | O36: =Dados!T35/Dados!V35 -> 3.4020915 | P36: =Dados!V36/Dados!O36 -> 0.044180482 | Q36: =Dados!W35/Dados!P35 -> 0.022027054 | R36: =Dados!W35/Dados!U35 -> 0.010404779 | S36: =Dados!X35/Dados!Y35 -> 2.6110502 | T36: =Dados!Z36/Dados!AA36 -> 0.9969248 | U36: =Dados!X36/Dados!AA36 -> 0.98139478 | V36: =Dados!AB35/Dados!X35 -> -0.10938622 | W36: =Dados!AC35/Dados!AE35 -> 0.49729079 | X36: =Dados!AE36/Dados!X36 -> 0.040593246 | Y36: =Dados!AF35/Dados!Y35 -> 0.034524177 | Z36: =Dados!AF35/Dados!AD35 -> 0.013222334 | AA36: =Dados!AG35/Dados!AH35 -> 0.23343533 | AB36: =Dados!AI36/Dados!AJ36 -> 0.98249184 | AC36: =Dados!AG36/Dados!AJ36 -> 1.0057624 | AD36: =Dados!AK35/Dados!AG35 -> 0.85503196 | AE36: =Dados!AL35/Dados!AN35 -> 14.337355 | AF36: =Dados!AN36/Dados!AG36 -> 0.013067734 | AG36: =Dados!AO35/Dados!AH35 -> 0.021741762 | AH36: =Dados!AO35/Dados!AM35 -> 0.093138267 | AI36: =Dados!AP35/Dados!AQ35 -> 0.15191577 | AJ36: =Dados!AR36/Dados!AS36 -> #DIV/0! | AK36: =Dados!AP36/Dados!AS36 -> #DIV/0! | AL36: =Dados!AT35/Dados!AP35 -> 0 | AM36: =Dados!AU35/Dados!AW35 -> 1.0219159 | AN36: =Dados!AW36/Dados!AP36 -> #DIV/0! | AO36: =Dados!AX35/Dados!AQ35 -> 0.021841556 | AP36: =Dados!AX35/Dados!AV35 -> 0.49995557
A37: 265 | B37: Consórcio Público Intermunicipal de Saúde da Região dos Grandes Lagos - CONSAGRA | C37: =Dados!F37/Dados!G37 -> 199.68691 | D37: =Dados!H37/Dados!I37 -> 0.99740548 | E37: =Dados!F37/Dados!I37 -> 1.0252353 | F37: =Dados!J37/Dados!F37 -> 0.024614113 | G37: =Dados!K37/Dados!M37 -> 5.9210339 | H37: =Dados!M37/Dados!F37 -> 0.01998859 | I37: =Dados!N37/Dados!G37 -> 0 | J37: =Dados!N37/Dados!L37 -> 0 | K37: =Dados!O36/Dados!P36 -> 238.51116 | L37: =Dados!Q37/Dados!R37 -> 0.9523596 | M37: =Dados!O37/Dados!R37 -> 1.0006078 | N37: =Dados!S36/Dados!O36 -> -0.015401471 | O37: =Dados!T36/Dados!V36 -> 0.48907828 | P37: =Dados!V37/Dados!O37 -> 0.019148735 | Q37: =Dados!W36/Dados!P36 -> 0 | R37: =Dados!W36/Dados!U36 -> 0 | S37: =Dados!X36/Dados!Y36 -> 226.1246 | T37: =Dados!Z37/Dados!AA37 -> 0.98485615 | U37: =Dados!X37/Dados!AA37 -> 1.0246025 | V37: =Dados!AB36/Dados!X36 -> -0.018957941 | W37: =Dados!AC36/Dados!AE36 -> 0.80575746 | X37: =Dados!AE37/Dados!X37 -> 0.015681515 | Y37: =Dados!AF36/Dados!Y36 -> 0 | Z37: =Dados!AF36/Dados!AD36 -> 0 | AA37: =Dados!AG36/Dados!AH36 -> 217.2564 | AB37: =Dados!AI37/Dados!AJ37 -> 0.99949195 | AC37: =Dados!AG37/Dados!AJ37 -> 1.0181435 | AD37: =Dados!AK36/Dados!AG36 -> 0.0057294134 | AE37: =Dados!AL36/Dados!AN36 -> 1.9989961 | AF37: =Dados!AN37/Dados!AG37 -> 0.012414879 | AG37: =Dados!AO36/Dados!AH36 -> 0 | AH37: =Dados!AO36/Dados!AM36 -> 0 | AI37: =Dados!AP36/Dados!AQ36 -> 0 | AJ37: =Dados!AR37/Dados!AS37 -> 0.99968281 | AK37: =Dados!AP37/Dados!AS37 -> 1.0112414 | AL37: =Dados!AT36/Dados!AP36 -> #DIV/0! | AM37: =Dados!AU36/Dados!AW36 -> 1.8780773 | AN37: =Dados!AW37/Dados!AP37 -> 0.020135958 | AO37: =Dados!AX36/Dados!AQ36 -> 0 | AP37: =Dados!AX36/Dados!AV36 -> #DIV/0!
A38: 266 | B38: Consórcio Intermunicipal do Extremo Noroeste de São Paulo - CIENSP | C38: =Dados!F38/Dados!G38 -> 88.252679 | D38: =Dados!H38/Dados!I38 -> 0.99916978 | E38: =Dados!F38/Dados!I38 -> 1.0179033 | F38: =Dados!J38/Dados!F38 -> 0.017588387 | G38: =Dados!K38/Dados!M38 -> 10.190327 | H38: =Dados!M38/Dados!F38 -> 0.0094174845 | I38: =Dados!N38/Dados!G38 -> 0 | J38: =Dados!N38/Dados!L38 -> 0 | K38: =Dados!O37/Dados!P37 -> 191.32132 | L38: =Dados!Q38/Dados!R38 -> 0.99821598 | M38: =Dados!O38/Dados!R38 -> 0.96646177 | N38: =Dados!S37/Dados!O37 -> 0.00060746435 | O38: =Dados!T37/Dados!V37 -> 5.706746 | P38: =Dados!V38/Dados!O38 -> 0.017396841 | Q38: =Dados!W37/Dados!P37 -> 0 | R38: =Dados!W37/Dados!U37 -> 0 | S38: =Dados!X37/Dados!Y37 -> 158.28871 | T38: =Dados!Z38/Dados!AA38 -> 0.99928387 | U38: =Dados!X38/Dados!AA38 -> 1.0199163 | V38: =Dados!AB37/Dados!X37 -> 0.02401174 | W38: =Dados!AC37/Dados!AE37 -> 7.737539 | X38: =Dados!AE38/Dados!X38 -> 0.044162823 | Y38: =Dados!AF37/Dados!Y37 -> 0 | Z38: =Dados!AF37/Dados!AD37 -> 0 | AA38: =Dados!AG37/Dados!AH37 -> 114.09731 | AB38: =Dados!AI38/Dados!AJ38 -> 0.97362117 | AC38: =Dados!AG38/Dados!AJ38 -> 0.97848273 | AD38: =Dados!AK37/Dados!AG37 -> 0.01782017 | AE38: =Dados!AL37/Dados!AN37 -> 9.5642369 | AF38: =Dados!AN38/Dados!AG38 -> 0.060482926 | AG38: =Dados!AO37/Dados!AH37 -> 0 | AH38: =Dados!AO37/Dados!AM37 -> 0 | AI38: =Dados!AP37/Dados!AQ37 -> 107.03684 | AJ38: =Dados!AR38/Dados!AS38 -> 0.99861534 | AK38: =Dados!AP38/Dados!AS38 -> 0.99347538 | AL38: =Dados!AT37/Dados!AP37 -> 0.01111648 | AM38: =Dados!AU37/Dados!AW37 -> 5.8993905 | AN38: =Dados!AW38/Dados!AP38 -> 0.063845604 | AO38: =Dados!AX37/Dados!AQ37 -> 0 | AP38: =Dados!AX37/Dados!AV37 -> 0
A39: 267 | B39: Consórcio Intermunicipal de Saúde - CIMSA | C39: =Dados!F39/Dados!G39 -> 207.88211 | D39: =Dados!H39/Dados!I39 -> 0.98982626 | E39: =Dados!F39/Dados!I39 -> 1.004639 | F39: =Dados!J39/Dados!F39 -> 0.0046175833 | G39: =Dados!K39/Dados!M39 -> 0.32478472 | H39: =Dados!M39/Dados!F39 -> 0.11263021 | I39: =Dados!N39/Dados!G39 -> 12.345007 | J39: =Dados!N39/Dados!L39 -> 0.059384651 | K39: =Dados!O38/Dados!P38 -> 43.536888 | L39: =Dados!Q39/Dados!R39 -> 0.9775834 | M39: =Dados!O39/Dados!R39 -> 0.92788315 | N39: =Dados!S38/Dados!O38 -> -0.034702076 | O39: =Dados!T38/Dados!V38 -> 5.0241849 | P39: =Dados!V39/Dados!O39 -> 0.13149722 | Q39: =Dados!W38/Dados!P38 -> 0 | R39: =Dados!W38/Dados!U38 -> 0 | S39: =Dados!X38/Dados!Y38 -> 33.956805 | T39: =Dados!Z39/Dados!AA39 -> 0.94630635 | U39: =Dados!X39/Dados!AA39 -> 0.994606 | V39: =Dados!AB38/Dados!X38 -> 0.019527405 | W39: =Dados!AC38/Dados!AE38 -> 1.8623354 | X39: =Dados!AE39/Dados!X39 -> 0.099012475 | Y39: =Dados!AF38/Dados!Y38 -> 0 | Z39: =Dados!AF38/Dados!AD38 -> 0 | AA39: =Dados!AG38/Dados!AH38 -> 26.203372 | AB39: =Dados!AI39/Dados!AJ39 -> 0.99151123 | AC39: =Dados!AG39/Dados!AJ39 -> 1.063454 | AD39: =Dados!AK38/Dados!AG38 -> -0.021990441 | AE39: =Dados!AL38/Dados!AN38 -> 1.3900067 | AF39: =Dados!AN39/Dados!AG39 -> 0.12877928 | AG39: =Dados!AO38/Dados!AH38 -> 0 | AH39: =Dados!AO38/Dados!AM38 -> 0 | AI39: =Dados!AP38/Dados!AQ38 -> 19.377816 | AJ39: =Dados!AR39/Dados!AS39 -> 1 | AK39: =Dados!AP39/Dados!AS39 -> 1.1297187 | AL39: =Dados!AT38/Dados!AP38 -> -0.0065674712 | AM39: =Dados!AU38/Dados!AW38 -> 1.9695762 | AN39: =Dados!AW39/Dados!AP39 -> 0.2222973 | AO39: =Dados!AX38/Dados!AQ38 -> 0 | AP39: =Dados!AX38/Dados!AV38 -> 0
A40: 268 | B40: Consórcio Intermunicipal de Saúde da Microrregião de Penápolis - CIMPE | C40: =Dados!F40/Dados!G40 -> 300.36235 | D40: =Dados!H40/Dados!I40 -> 0.99964897 | E40: =Dados!F40/Dados!I40 -> 1.0487193 | F40: =Dados!J40/Dados!F40 -> 0.046456015 | G40: =Dados!K40/Dados!M40 -> 2.5334053 | H40: =Dados!M40/Dados!F40 -> 0.086157869 | I40: =Dados!N40/Dados!G40 -> 0 | J40: =Dados!N40/Dados!L40 -> 0 | K40: =Dados!O39/Dados!P39 -> 131.5078 | L40: =Dados!Q40/Dados!R40 -> 0.99985417 | M40: =Dados!O40/Dados!R40 -> 0.99938805 | N40: =Dados!S39/Dados!O39 -> -0.077721907 | O40: =Dados!T39/Dados!V39 -> 0.045475729 | P40: =Dados!V40/Dados!O40 -> 0.082177361 | Q40: =Dados!W39/Dados!P39 -> 13.715292 | R40: =Dados!W39/Dados!U39 -> 0.10429262 | S40: =Dados!X39/Dados!Y39 -> 108.79084 | T40: =Dados!Z40/Dados!AA40 -> 0.99993076 | U40: =Dados!X40/Dados!AA40 -> 1.0118492 | V40: =Dados!AB39/Dados!X39 -> -0.0054232565 | W40: =Dados!AC39/Dados!AE39 -> 0.40213694 | X40: =Dados!AE40/Dados!X40 -> 0.079015611 | Y40: =Dados!AF39/Dados!Y39 -> 15.771432 | Z40: =Dados!AF39/Dados!AD39 -> 0.14497022 | AA40: =Dados!AG39/Dados!AH39 -> 87.859226 | AB40: =Dados!AI40/Dados!AJ40 -> 0.99983051 | AC40: =Dados!AG40/Dados!AJ40 -> 1.0523656 | AD40: =Dados!AK39/Dados!AG39 -> 0.059667849 | AE40: =Dados!AL39/Dados!AN39 -> 0.8690959 | AF40: =Dados!AN40/Dados!AG40 -> 0.081619352 | AG40: =Dados!AO39/Dados!AH39 -> 19.454741 | AH40: =Dados!AO39/Dados!AM39 -> 0.22143083 | AI40: =Dados!AP39/Dados!AQ39 -> 80.022064 | AJ40: =Dados!AR40/Dados!AS40 -> #DIV/0! | AK40: =Dados!AP40/Dados!AS40 -> #DIV/0! | AL40: =Dados!AT39/Dados!AP39 -> 0.11482393 | AM40: =Dados!AU39/Dados!AW39 -> 0.40308725 | AN40: =Dados!AW40/Dados!AP40 -> #DIV/0! | AO40: =Dados!AX39/Dados!AQ39 -> 24.423984 | AP40: =Dados!AX39/Dados!AV39 -> 0.30521562
A41: 269 | B41: Consórcio Regional Intermunicipal de Saúde - CRIS | C41: =Dados!F41/Dados!G41 -> 2.0101335 | D41: =Dados!H41/Dados!I41 -> 0.91145107 | E41: =Dados!F41/Dados!I41 -> 0.85195808 | F41: =Dados!J41/Dados!F41 -> -0.17376667 | G41: =Dados!K41/Dados!M41 -> 12.330177 | H41: =Dados!M41/Dados!F41 -> 0.011254394 | I41: =Dados!N41/Dados!G41 -> 0 | J41: =Dados!N41/Dados!L41 -> 0 | K41: =Dados!O40/Dados!P40 -> 264.47028 | L41: =Dados!Q41/Dados!R41 -> 0.75439087 | M41: =Dados!O41/Dados!R41 -> 0.6297879 | N41: =Dados!S40/Dados!O40 -> -0.00061232033 | O41: =Dados!T40/Dados!V40 -> 2.0934425 | P41: =Dados!V41/Dados!O41 -> 0.019573336 | Q41: =Dados!W40/Dados!P40 -> 0 | R41: =Dados!W40/Dados!U40 -> 0 | S41: =Dados!X40/Dados!Y40 -> 230.98794 | T41: =Dados!Z41/Dados!AA41 -> 0.13765128 | U41: =Dados!X41/Dados!AA41 -> 0.8702825 | V41: =Dados!AB40/Dados!X40 -> 0.011710422 | W41: =Dados!AC40/Dados!AE40 -> 2.1646162 | X41: =Dados!AE41/Dados!X41 -> 0.0067538148 | Y41: =Dados!AF40/Dados!Y40 -> 0 | Z41: =Dados!AF40/Dados!AD40 -> 0 | AA41: =Dados!AG40/Dados!AH40 -> 216.21328 | AB41: =Dados!AI41/Dados!AJ41 -> 1 | AC41: =Dados!AG41/Dados!AJ41 -> 2.0183929 | AD41: =Dados!AK40/Dados!AG40 -> 0.049759856 | AE41: =Dados!AL40/Dados!AN40 -> 1.7180559 | AF41: =Dados!AN41/Dados!AG41 -> 0.060537889 | AG41: =Dados!AO40/Dados!AH40 -> 0 | AH41: =Dados!AO40/Dados!AM40 -> 0 | AI41: =Dados!AP40/Dados!AQ40 -> 0 | AJ41: =Dados!AR41/Dados!AS41 -> 0.82565327 | AK41: =Dados!AP41/Dados!AS41 -> 1.5700668 | AL41: =Dados!AT40/Dados!AP40 -> #DIV/0! | AM41: =Dados!AU40/Dados!AW40 -> 1.3082511 | AN41: =Dados!AW41/Dados!AP41 -> 0.040218743 | AO41: =Dados!AX40/Dados!AQ40 -> 0 | AP41: =Dados!AX40/Dados!AV40 -> #DIV/0!
A42: 270 | B42: Consórcio de Desenvolvimento do Vale do Rio Grande - CODEVAR | C42: =Dados!F42/Dados!G42 -> 0 | D42: =Dados!H42/Dados!I42 -> #DIV/0! | E42: =Dados!F42/Dados!I42 -> #DIV/0! | F42: =Dados!J42/Dados!F42 -> #DIV/0! | G42: =Dados!K42/Dados!M42 -> #DIV/0! | H42: =Dados!M42/Dados!F42 -> #DIV/0! | I42: =Dados!N42/Dados!G42 -> 0 | J42: =Dados!N42/Dados!L42 -> #DIV/0! | K42: =Dados!O41/Dados!P41 -> 1.0267853 | L42: =Dados!Q42/Dados!R42 -> 0.99794858 | M42: =Dados!O42/Dados!R42 -> 1.0151627 | N42: =Dados!S41/Dados!O41 -> -0.58783616 | O42: =Dados!T41/Dados!V41 -> 32.494075 | P42: =Dados!V42/Dados!O42 -> 0.0058622017 | Q42: =Dados!W41/Dados!P41 -> 0 | R42: =Dados!W41/Dados!U41 -> 0 | S42: =Dados!X41/Dados!Y41 -> 3.8152427 | T42: =Dados!Z42/Dados!AA42 -> 0.98901208 | U42: =Dados!X42/Dados!AA42 -> 0.98476215 | V42: =Dados!AB41/Dados!X41 -> -0.14905217 | W42: =Dados!AC41/Dados!AE41 -> 46.344235 | X42: =Dados!AE42/Dados!X42 -> 0.010433704 | Y42: =Dados!AF41/Dados!Y41 -> 0 | Z42: =Dados!AF41/Dados!AD41 -> 0 | AA42: =Dados!AG41/Dados!AH41 -> 1.0650083 | AB42: =Dados!AI42/Dados!AJ42 -> 0.9963678 | AC42: =Dados!AG42/Dados!AJ42 -> 1.0105659 | AD42: =Dados!AK41/Dados!AG41 -> 0.50455632 | AE42: =Dados!AL41/Dados!AN41 -> 15.255996 | AF42: =Dados!AN42/Dados!AG42 -> 0.0093642689 | AG42: =Dados!AO41/Dados!AH41 -> 0 | AH42: =Dados!AO41/Dados!AM41 -> 0 | AI42: =Dados!AP41/Dados!AQ41 -> 0.88737385 | AJ42: =Dados!AR42/Dados!AS42 -> #DIV/0! | AK42: =Dados!AP42/Dados!AS42 -> #DIV/0! | AL42: =Dados!AT41/Dados!AP41 -> 0.36308444 | AM42: =Dados!AU41/Dados!AW41 -> 11.494049 | AN42: =Dados!AW42/Dados!AP42 -> #DIV/0! | AO42: =Dados!AX41/Dados!AQ41 -> 0 | AP42: =Dados!AX41/Dados!AV41 -> 0
A43: 272 | B43: Consórcio Intermunicipal de Saúde do Circuito das Águas - CONISCA | C43: =Dados!F43/Dados!G43 -> 233.9133 | D43: =Dados!H43/Dados!I43 -> 0.99984661 | E43: =Dados!F43/Dados!I43 -> 0.98541276 | F43: =Dados!J43/Dados!F43 -> -0.014803176 | G43: =Dados!K43/Dados!M43 -> 0.001700513 | H43: =Dados!M43/Dados!F43 -> 0.039764691 | I43: =Dados!N43/Dados!G43 -> 1.6858244 | J43: =Dados!N43/Dados!L43 -> 0.007207048 | K43: =Dados!O42/Dados!P42 -> 355.51107 | L43: =Dados!Q43/Dados!R43 -> 0.99958002 | M43: =Dados!O43/Dados!R43 -> 1.0041249 | N43: =Dados!S42/Dados!O42 -> 0.014936238 | O43: =Dados!T42/Dados!V42 -> 4.0757052 | P43: =Dados!V43/Dados!O43 -> 0.015472851 | Q43: =Dados!W42/Dados!P42 -> 4.9512326 | R43: =Dados!W42/Dados!U42 -> 0.013927084 | S43: =Dados!X42/Dados!Y42 -> 282.31583 | T43: =Dados!Z43/Dados!AA43 -> 0.99687903 | U43: =Dados!X43/Dados!AA43 -> 1.0030715 | V43: =Dados!AB42/Dados!X42 -> -0.015473631 | W43: =Dados!AC42/Dados!AE42 -> 1.5251162 | X43: =Dados!AE43/Dados!X43 -> 0.014444084 | Y43: =Dados!AF42/Dados!Y42 -> 5.802077 | Z43: =Dados!AF42/Dados!AD42 -> 0.020591466 | AA43: =Dados!AG42/Dados!AH42 -> 225.1247 | AB43: =Dados!AI43/Dados!AJ43 -> 0.99171288 | AC43: =Dados!AG43/Dados!AJ43 -> 1.0090422 | AD43: =Dados!AK42/Dados!AG42 -> 0.010455393 | AE43: =Dados!AL42/Dados!AN42 -> 3.5632482 | AF43: =Dados!AN43/Dados!AG43 -> 0.020919745 | AG43: =Dados!AO42/Dados!AH42 -> 6.3294807 | AH43: =Dados!AO42/Dados!AM42 -> 0.028115443 | AI43: =Dados!AP42/Dados!AQ42 -> 0 | AJ43: =Dados!AR43/Dados!AS43 -> 0.9998933 | AK43: =Dados!AP43/Dados!AS43 -> 1.00876 | AL43: =Dados!AT42/Dados!AP42 -> #DIV/0! | AM43: =Dados!AU42/Dados!AW42 -> 1.9277199 | AN43: =Dados!AW43/Dados!AP43 -> 0.031110101 | AO43: =Dados!AX42/Dados!AQ42 -> 7.0016192 | AP43: =Dados!AX42/Dados!AV42 -> #DIV/0!
A44: 273 | B44: Consórcio Intermunicipal de Saúde da Região Metropolitana de Campinas - CISMETRO | C44: =Dados!F44/Dados!G44 -> 112.36952 | D44: =Dados!H44/Dados!I44 -> 0.97978232 | E44: =Dados!F44/Dados!I44 -> 0.9843818 | F44: =Dados!J44/Dados!F44 -> -0.015865999 | G44: =Dados!K44/Dados!M44 -> 0.45037824 | H44: =Dados!M44/Dados!F44 -> 0.053109815 | I44: =Dados!N44/Dados!G44 -> 1.436708 | J44: =Dados!N44/Dados!L44 -> 0.012911032 | K44: =Dados!O43/Dados!P43 -> 192.28957 | L44: =Dados!Q44/Dados!R44 -> 0.99835853 | M44: =Dados!O44/Dados!R44 -> 1.0163283 | N44: =Dados!S43/Dados!O43 -> 0.0041079722 | O44: =Dados!T43/Dados!V43 -> 0.040555501 | P44: =Dados!V44/Dados!O44 -> 0.023937377 | Q44: =Dados!W43/Dados!P43 -> 1.6741579 | R44: =Dados!W43/Dados!U43 -> 0.0087064416 | S44: =Dados!X43/Dados!Y43 -> 155.14064 | T44: =Dados!Z44/Dados!AA44 -> #DIV/0! | U44: =Dados!X44/Dados!AA44 -> #DIV/0! | V44: =Dados!AB43/Dados!X43 -> 0.0030620825 | W44: =Dados!AC43/Dados!AE43 -> 0.057999294 | X44: =Dados!AE44/Dados!X44 -> #DIV/0! | Y44: =Dados!AF43/Dados!Y43 -> 0 | Z44: =Dados!AF43/Dados!AD43 -> 0 | AA44: =Dados!AG43/Dados!AH43 -> 98.626899 | AB44: =Dados!AI44/Dados!AJ44 -> 0.99845103 | AC44: =Dados!AG44/Dados!AJ44 -> 0.99417898 | AD44: =Dados!AK43/Dados!AG43 -> 0.0089612082 | AE44: =Dados!AL43/Dados!AN43 -> 0.0058557053 | AF44: =Dados!AN44/Dados!AG44 -> 0.087065154 | AG44: =Dados!AO43/Dados!AH43 -> 0 | AH44: =Dados!AO43/Dados!AM43 -> 0 | AI44: =Dados!AP43/Dados!AQ43 -> 67.146119 | AJ44: =Dados!AR44/Dados!AS44 -> 0.99589227 | AK44: =Dados!AP44/Dados!AS44 -> 1.0237198 | AL44: =Dados!AT43/Dados!AP43 -> 0.0086839679 | AM44: =Dados!AU43/Dados!AW43 -> 0.0058557053 | AN44: =Dados!AW44/Dados!AP44 -> 0.017787155 | AO44: =Dados!AX43/Dados!AQ43 -> 0 | AP44: =Dados!AX43/Dados!AV43 -> 0
... A114: 13 | B114: Consórcio Intermunicipal de Saúde da Região do Garças/Araguaia CISRGA | C114: =Dados!F114/Dados!G114 -> 0 | D114: =Dados!H114/Dados!I114 -> #DIV/0! | E114: =Dados!F114/Dados!I114 -> #DIV/0! | F114: =Dados!J114/Dados!F114 -> #DIV/0! | G114: =Dados!K114/Dados!M114 -> #DIV/0! | H114: =Dados!M114/Dados!F114 -> #DIV/0! | I114: =Dados!N114/Dados!G114 -> 0 | J114: =Dados!N114/Dados!L114 -> #DIV/0! | K114: =Dados!O113/Dados!P113 -> 42.196487 | L114: =Dados!Q114/Dados!R114 -> #DIV/0! | M114: =Dados!O114/Dados!R114 -> #DIV/0! | N114: =Dados!S113/Dados!O113 -> 0.062919712 | O114: =Dados!T113/Dados!V113 -> 6.563383 | P114: =Dados!V114/Dados!O114 -> #DIV/0! | Q114: =Dados!W113/Dados!P113 -> 0 | R114: =Dados!W113/Dados!U113 -> 0 | S114: =Dados!X113/Dados!Y113 -> 0 | T114: =Dados!Z114/Dados!AA114 -> 0.59742755 | U114: =Dados!X114/Dados!AA114 -> 1.1998917 | V114: =Dados!AB113/Dados!X113 -> #DIV/0! | W114: =Dados!AC113/Dados!AE113 -> #DIV/0! | X114: =Dados!AE114/Dados!X114 -> 0.00063369164 | Y114: =Dados!AF113/Dados!Y113 -> 0 | Z114: =Dados!AF113/Dados!AD113 -> #DIV/0! | AA114: =Dados!AG113/Dados!AH113 -> 0 | AB114: =Dados!AI114/Dados!AJ114 -> 0.99074351 | AC114: =Dados!AG114/Dados!AJ114 -> 1.1722029 | AD114: =Dados!AK113/Dados!AG113 -> #DIV/0! | AE114: =Dados!AL113/Dados!AN113 -> #DIV/0! | AF114: =Dados!AN114/Dados!AG114 -> 0.54915335 | AG114: =Dados!AO113/Dados!AH113 -> 0 | AH114: =Dados!AO113/Dados!AM113 -> #DIV/0! | AI114: =Dados!AP113/Dados!AQ113 -> 0 | AJ114: =Dados!AR114/Dados!AS114 -> 0.43077001 | AK114: =Dados!AP114/Dados!AS114 -> 1.0577937 | AL114: =Dados!AT113/Dados!AP113 -> #DIV/0! | AM114: =Dados!AU113/Dados!AW113 -> #DIV/0! | AN114: =Dados!AW114/Dados!AP114 -> 0.53858001 | AO114: =Dados!AX113/Dados!AQ113 -> 0 | AP114: =Dados!AX113/Dados!AV113 -> #DIV/0!
A115: 17 | B115: Consórcio Intermunicipal Para o Desenvolvimento Sustentável da Bacia do Rio Taquari COINTA | C115: =Dados!F115/Dados!G115 -> 0.0019758849 | D115: =Dados!H115/Dados!I115 -> 1 | E115: =Dados!F115/Dados!I115 -> 0.204339 | F115: =Dados!J115/Dados!F115 -> 0 | G115: =Dados!K115/Dados!M115 -> 75.241941 | H115: =Dados!M115/Dados!F115 -> 0.062554623 | I115: =Dados!N115/Dados!G115 -> 0 | J115: =Dados!N115/Dados!L115 -> 0 | K115: =Dados!O114/Dados!P114 -> 0 | L115: =Dados!Q115/Dados!R115 -> 1 | M115: =Dados!O115/Dados!R115 -> 0.64660781 | N115: =Dados!S114/Dados!O114 -> #DIV/0! | O115: =Dados!T114/Dados!V114 -> #DIV/0! | P115: =Dados!V115/Dados!O115 -> 0.015243687 | Q115: =Dados!W114/Dados!P114 -> 0 | R115: =Dados!W114/Dados!U114 -> #DIV/0! | S115: =Dados!X114/Dados!#REF! -> #REF! | T115: =Dados!Z115/Dados!AA115 -> #DIV/0! | U115: =Dados!X115/Dados!AA115 -> #DIV/0! | V115: =Dados!AB114/Dados!X114 -> 0.16659142 | W115: =Dados!AC114/Dados!AE114 -> 372.49804 | X115: =Dados!AE115/Dados!X115 -> #DIV/0! | Y115: =Dados!AF114/Dados!#REF! -> #REF! | Z115: =Dados!AF114/Dados!AD114 -> 0 | AA115: =Dados!AG114/Dados!AH114 -> 6.6925431 | AB115: =Dados!AI115/Dados!AJ115 -> #DIV/0! | AC115: =Dados!AG115/Dados!AJ115 -> #DIV/0! | AD115: =Dados!AK114/Dados!AG114 -> 0.14690536 | AE115: =Dados!AL114/Dados!AN114 -> 0.5342478 | AF115: =Dados!AN115/Dados!AG115 -> #DIV/0! | AG115: =Dados!AO114/Dados!AH114 -> 0 | AH115: =Dados!AO114/Dados!AM114 -> 0 | AI115: =Dados!AP114/Dados!AQ114 -> 6.7377147 | AJ115: =Dados!AR115/Dados!AS115 -> #DIV/0! | AK115: =Dados!AP115/Dados!AS115 -> #DIV/0! | AL115: =Dados!AT114/Dados!AP114 -> 0.054636103 | AM115: =Dados!AU114/Dados!AW114 -> 0.25202574 | AN115: =Dados!AW115/Dados!AP115 -> #DIV/0! | AO115: =Dados!AX114/Dados!AQ114 -> 0 | AP115: =Dados!AX114/Dados!AV114 -> 0
A116: 84 | B116: Consórcio Nacional de Vacinas das Cidades Brasileiras - CONECTAR | C116: =Dados!F116/Dados!G116 -> 4.7726828 | D116: =Dados!H116/Dados!I116 -> 1 | E116: =Dados!F116/Dados!I116 -> 1.7269848 | F116: =Dados!J116/Dados!F116 -> 0.42095612 | G116: =Dados!K116/Dados!M116 -> 22.229598 | H116: =Dados!M116/Dados!F116 -> 0.023958399 | I116: =Dados!N116/Dados!G116 -> 0 | J116: =Dados!N116/Dados!L116 -> 0 | K116: =Dados!O115/Dados!P115 -> 0.005376303 | L116: =Dados!Q116/Dados!R116 -> 1 | M116: =Dados!O116/Dados!R116 -> 0.88471937 | N116: =Dados!S115/Dados!O115 -> -0.54653251 | O116: =Dados!T115/Dados!V115 -> 206.39106 | P116: =Dados!V116/Dados!O116 -> 0 | Q116: =Dados!W115/Dados!P115 -> 0 | R116: =Dados!W115/Dados!U115 -> 0 | S116: =Dados!X115/Dados!Y114 -> 0 | T116: =Dados!Z116/Dados!AA116 -> 1 | U116: =Dados!X116/Dados!AA116 -> 0.83222669 | V116: =Dados!AB115/Dados!X115 -> #DIV/0! | W116: =Dados!AC115/Dados!AE115 -> #DIV/0! | X116: =Dados!AE116/Dados!X116 -> 0 | Y116: =Dados!AF115/Dados!Y114 -> 0 | Z116: =Dados!AF115/Dados!AD115 -> #DIV/0! | AA116: =Dados!AG115/Dados!AH115 -> 0 | AB116: =Dados!AI116/Dados!AJ116 -> 1 | AC116: =Dados!AG116/Dados!AJ116 -> 1.0757296 | AD116: =Dados!AK115/Dados!AG115 -> #DIV/0! | AE116: =Dados!AL115/Dados!AN115 -> #DIV/0! | AF116: =Dados!AN116/Dados!AG116 -> 0 | AG116: =Dados!AO115/Dados!AH115 -> 0 | AH116: =Dados!AO115/Dados!AM115 -> #DIV/0! | AI116: =Dados!AP115/Dados!AQ115 -> 0 | AJ116: =Dados!AR116/Dados!AS116 -> 1 | AK116: =Dados!AP116/Dados!AS116 -> 1.1028839 | AL116: =Dados!AT115/Dados!AP115 -> #DIV/0! | AM116: =Dados!AU115/Dados!AW115 -> #DIV/0! | AN116: =Dados!AW116/Dados!AP116 -> 0 | AO116: =Dados!AX115/Dados!AQ115 -> 0 | AP116: =Dados!AX115/Dados!AV115 -> #DIV/0!
A117: 184 | B117: Consórcio Intermunicipal Para o Desenvolvimento da Costa Leste - CIDECOL | C117: =Dados!F117/Dados!G117 -> 104.61993 | D117: =Dados!H117/Dados!I117 -> 1 | E117: =Dados!F117/Dados!I117 -> 1.0524169 | F117: =Dados!J117/Dados!F117 -> 0.049806201 | G117: =Dados!K117/Dados!M117 -> 1552.1083 | H117: =Dados!M117/Dados!F117 -> 7.902467e-05 | I117: =Dados!N117/Dados!G117 -> 0 | J117: =Dados!N117/Dados!L117 -> 0 | K117: =Dados!O116/Dados!P116 -> 2.1493666 | L117: =Dados!Q117/Dados!R117 -> 0.99876881 | M117: =Dados!O117/Dados!R117 -> 1.0113765 | N117: =Dados!S116/Dados!O116 -> -0.13030192 | O117: =Dados!T116/Dados!V116 -> #DIV/0! | P117: =Dados!V117/Dados!O117 -> 0.0052826633 | Q117: =Dados!W116/Dados!P116 -> 0 | R117: =Dados!W116/Dados!U116 -> 0 | S117: =Dados!X116/Dados!Y116 -> 1.5361761 | T117: =Dados!Z117/Dados!AA117 -> 0.99782619 | U117: =Dados!X117/Dados!AA117 -> 1.0570024 | V117: =Dados!AB116/Dados!X116 -> -0.20159569 | W117: =Dados!AC116/Dados!AE116 -> #DIV/0! | X117: =Dados!AE117/Dados!X117 -> 0.00096720393 | Y117: =Dados!AF116/Dados!Y116 -> 0 | Z117: =Dados!AF116/Dados!AD116 -> 0 | AA117: =Dados!AG116/Dados!AH116 -> 1.702322 | AB117: =Dados!AI117/Dados!AJ117 -> 0.99959616 | AC117: =Dados!AG117/Dados!AJ117 -> 1.0018604 | AD117: =Dados!AK116/Dados!AG116 -> 0.070398331 | AE117: =Dados!AL116/Dados!AN116 -> #DIV/0! | AF117: =Dados!AN117/Dados!AG117 -> 0 | AG117: =Dados!AO116/Dados!AH116 -> 0 | AH117: =Dados!AO116/Dados!AM116 -> 0 | AI117: =Dados!AP116/Dados!AQ116 -> 1.4232872 | AJ117: =Dados!AR117/Dados!AS117 -> #DIV/0! | AK117: =Dados!AP117/Dados!AS117 -> #DIV/0! | AL117: =Dados!AT116/Dados!AP116 -> 0.093286222 | AM117: =Dados!AU116/Dados!AW116 -> #DIV/0! | AN117: =Dados!AW117/Dados!AP117 -> #DIV/0! | AO117: =Dados!AX116/Dados!AQ116 -> 0 | AP117: =Dados!AX116/Dados!AV116 -> 0
A118: 185 | B118: Consórcio Intermunicipal de Saúde da Região do Alto Tapajós - CISRAT | C118: =Dados!F118/Dados!G118 -> 58.832739 | D118: =Dados!H118/Dados!I118 -> 1 | E118: =Dados!F118/Dados!I118 -> 1.0380477 | F118: =Dados!J118/Dados!F118 -> -0.074437078 | G118: =Dados!K118/Dados!M118 -> #DIV/0! | H118: =Dados!M118/Dados!F118 -> 0 | I118: =Dados!N118/Dados!G118 -> 0 | J118: =Dados!N118/Dados!L118 -> 0 | K118: =Dados!O117/Dados!P117 -> 62.386913 | L118: =Dados!Q118/Dados!R118 -> #DIV/0! | M118: =Dados!O118/Dados!R118 -> #DIV/0! | N118: =Dados!S117/Dados!O117 -> 0.01124849 | O118: =Dados!T117/Dados!V117 -> 16.406477 | P118: =Dados!V118/Dados!O118 -> 0 | Q118: =Dados!W117/Dados!P117 -> 0 | R118: =Dados!W117/Dados!U117 -> 0 | S118: =Dados!X117/Dados!Y117 -> 47.696951 | T118: =Dados!Z118/Dados!AA118 -> #DIV/0! | U118: =Dados!X118/Dados!AA118 -> #DIV/0! | V118: =Dados!AB117/Dados!X117 -> 0.053928386 | W118: =Dados!AC117/Dados!AE117 -> 95.844318 | X118: =Dados!AE118/Dados!X118 -> #DIV/0! | Y118: =Dados!AF117/Dados!Y117 -> 0 | Z118: =Dados!AF117/Dados!AD117 -> 0 | AA118: =Dados!AG117/Dados!AH117 -> 35.615252 | AB118: =Dados!AI118/Dados!AJ118 -> #DIV/0! | AC118: =Dados!AG118/Dados!AJ118 -> #DIV/0! | AD118: =Dados!AK117/Dados!AG117 -> 0.001856942 | AE118: =Dados!AL117/Dados!AN117 -> #DIV/0! | AF118: =Dados!AN118/Dados!AG118 -> #DIV/0! | AG118: =Dados!AO117/Dados!AH117 -> 0 | AH118: =Dados!AO117/Dados!AM117 -> 0 | AI118: =Dados!AP117/Dados!AQ117 -> 0 | AJ118: =Dados!AR118/Dados!AS118 -> #DIV/0! | AK118: =Dados!AP118/Dados!AS118 -> #DIV/0! | AL118: =Dados!AT117/Dados!AP117 -> #DIV/0! | AM118: =Dados!AU117/Dados!AW117 -> #DIV/0! | AN118: =Dados!AW118/Dados!AP118 -> #DIV/0! | AO118: =Dados!AX117/Dados!AQ117 -> 0 | AP118: =Dados!AX117/Dados!AV117 -> #DIV/0!
A119: 186 | B119: Consórcio Intermunicipal de Saúde da Região Norte Matogrossense - CISRNM | C119: =Dados!F119/Dados!G119 -> 150.9136 | D119: =Dados!H119/Dados!I119 -> 0.97912805 | E119: =Dados!F119/Dados!I119 -> 0.92009523 | F119: =Dados!J119/Dados!F119 -> -0.086844021 | G119: =Dados!K119/Dados!M119 -> 39.548007 | H119: =Dados!M119/Dados!F119 -> 0.0074966953 | I119: =Dados!N119/Dados!G119 -> 0 | J119: =Dados!N119/Dados!L119 -> 0 | K119: =Dados!O118/Dados!P118 -> 59.658309 | L119: =Dados!Q119/Dados!R119 -> 0.98201148 | M119: =Dados!O119/Dados!R119 -> 1.153587 | N119: =Dados!S118/Dados!O118 -> 0 | O119: =Dados!T118/Dados!V118 -> #DIV/0! | P119: =Dados!V119/Dados!O119 -> 0.00011132668 | Q119: =Dados!W118/Dados!P118 -> 0 | R119: =Dados!W118/Dados!U118 -> 0 | S119: =Dados!X118/Dados!Y118 -> 0 | T119: =Dados!Z119/Dados!AA119 -> 0.99547191 | U119: =Dados!X119/Dados!AA119 -> 1.0371629 | V119: =Dados!AB118/Dados!X118 -> #DIV/0! | W119: =Dados!AC118/Dados!AE118 -> #DIV/0! | X119: =Dados!AE119/Dados!X119 -> 0.00081693157 | Y119: =Dados!AF118/Dados!Y118 -> 0 | Z119: =Dados!AF118/Dados!AD118 -> #DIV/0! | AA119: =Dados!AG118/Dados!AH118 -> 0 | AB119: =Dados!AI119/Dados!AJ119 -> 0.95404704 | AC119: =Dados!AG119/Dados!AJ119 -> 1.2658528 | AD119: =Dados!AK118/Dados!AG118 -> #DIV/0! | AE119: =Dados!AL118/Dados!AN118 -> #DIV/0! | AF119: =Dados!AN119/Dados!AG119 -> 0 | AG119: =Dados!AO118/Dados!AH118 -> 0 | AH119: =Dados!AO118/Dados!AM118 -> #DIV/0! | AI119: =Dados!AP118/Dados!AQ118 -> 0 | AJ119: =Dados!AR119/Dados!AS119 -> 0.94431699 | AK119: =Dados!AP119/Dados!AS119 -> 1.0294759 | AL119: =Dados!AT118/Dados!AP118 -> #DIV/0! | AM119: =Dados!AU118/Dados!AW118 -> #DIV/0! | AN119: =Dados!AW119/Dados!AP119 -> 0.00010377432 | AO119: =Dados!AX118/Dados!AQ118 -> 0 | AP119: =Dados!AX118/Dados!AV118 -> #DIV/0!
A120: 187 | B120: Consórcio Público de Saúde Vale do Teles Pires - CONSÓRCIO VALE DO TELES PIRES | C120: =Dados!F120/Dados!G120 -> 0 | D120: =Dados!H120/Dados!I120 -> #DIV/0! | E120: =Dados!F120/Dados!I120 -> #DIV/0! | F120: =Dados!J120/Dados!F120 -> #DIV/0! | G120: =Dados!K120/Dados!M120 -> #DIV/0! | H120: =Dados!M120/Dados!F120 -> #DIV/0! | I120: =Dados!N120/Dados!G120 -> 0 | J120: =Dados!N120/Dados!L120 -> #DIV/0! | K120: =Dados!O119/Dados!P119 -> 147.37848 | L120: =Dados!Q120/Dados!R120 -> 1 | M120: =Dados!O120/Dados!R120 -> 0.60554602 | N120: =Dados!S119/Dados!O119 -> 0.13313866 | O120: =Dados!T119/Dados!V119 -> 3406.5285 | P120: =Dados!V120/Dados!O120 -> 0.47404789 | Q120: =Dados!W119/Dados!P119 -> 0 | R120: =Dados!W119/Dados!U119 -> 0 | S120: =Dados!X119/Dados!Y119 -> 105.98701 | T120: =Dados!Z120/Dados!AA120 -> 0.99806747 | U120: =Dados!X120/Dados!AA120 -> 0.38107367 | V120: =Dados!AB119/Dados!X119 -> 0.035831321 | W120: =Dados!AC119/Dados!AE119 -> 416.82579 | X120: =Dados!AE120/Dados!X120 -> 0.45168726 | Y120: =Dados!AF119/Dados!Y119 -> 0 | Z120: =Dados!AF119/Dados!AD119 -> 0 | AA120: =Dados!AG119/Dados!AH119 -> 95.848782 | AB120: =Dados!AI120/Dados!AJ120 -> 0.99855418 | AC120: =Dados!AG120/Dados!AJ120 -> 0.38615995 | AD120: =Dados!AK119/Dados!AG119 -> 0.21001871 | AE120: =Dados!AL119/Dados!AN119 -> #DIV/0! | AF120: =Dados!AN120/Dados!AG120 -> 0.3279217 | AG120: =Dados!AO119/Dados!AH119 -> 0 | AH120: =Dados!AO119/Dados!AM119 -> 0 | AI120: =Dados!AP119/Dados!AQ119 -> 65.675071 | AJ120: =Dados!AR120/Dados!AS120 -> 0.9986319 | AK120: =Dados!AP120/Dados!AS120 -> 0.44194459 | AL120: =Dados!AT119/Dados!AP119 -> 0.028631931 | AM120: =Dados!AU119/Dados!AW119 -> 1630.4984 | AN120: =Dados!AW120/Dados!AP120 -> 0.68878691 | AO120: =Dados!AX119/Dados!AQ119 -> 0 | AP120: =Dados!AX119/Dados!AV119 -> 0
