Workbook

Sheet Fatores determinantes
A1: ID | B1: Nome | C1: CNPJ | D1: Estado | E1: Região | F1: Idade | G1: População atendida | L1: Número de municípios consorciados | M1: Localização | N1: Quantidade de áreas de atuação | O1: Índice Firjan | S1: Saneamento Básico Censo 2022 | V1: Gasto per capita | AA1: Covid | AF1: Despesa com pessoal/Despesa Total | AK1: Produção ambulatorial per capita
G2: 2024 | H2: 2023 | I2: 2022 | J2: 2021 | K2: 2020 | O2: 2023 | P2: 2022 | Q2: 2021 | R2: 2020 | S2: Conexão a rede de esgoto (percentual) | T2: Abastecimento de água pela rede geral (percentual) | U2: Coleta de lixo (percentual) | V2: 2024 | W2: 2023 | X2: 2022 | Y2: 2021 | Z2: 2020 | AA2: 2024 | AB2: 2023 | AC2: 2022 | AD2: 2021 | AE2: 2020 | AF2: 2024 | AG2: 2023 | AH2: 2022 | AI2: 2021 | AJ2: 2020 | AK2: 2024 | AL2: 2023 | AM2: 2022 | AN2: 2021 | AO2: 2020
A3: 9 | B3: Consórcio Público da Região Polo Sul - CIM POLO SUL | C3: 02.722.566/0001-52 | D3: Espirito Santo | E3: Sudeste | F3: =_xlfn.XLOOKUP(C3,Dados!$C$3:$C$329,Dados!$D$3:$D$329,"") -> 26 | G3: =_xlfn.XLOOKUP(C3,Dados!$C$3:$C$329,Dados!$E$3:$E$329,"") -> 651242 | H3: =_xlfn.XLOOKUP(C3,Dados!$C$3:$C$329,Dados!$F$3:$F$329,"") -> 648960.33 | I3: =_xlfn.XLOOKUP(C3,Dados!$C$3:$C$329,Dados!$G$3:$G$329,"") -> 646678.67 | J3: =_xlfn.XLOOKUP(C3,Dados!$C$3:$C$329,Dados!$H$3:$H$329,"") -> 644397 | K3: =_xlfn.XLOOKUP(C3,Dados!$C$3:$C$329,Dados!$I$3:$I$329,"") -> 641058 | L3: =_xlfn.XLOOKUP(C3,Dados!$C$3:$C$329,Dados!$J$3:$J$329,"") -> 25 | M3: =_xlfn.XLOOKUP(C3,Dados!$C$3:$C$329,Dados!$K$3:$K$329,"") -> Sudeste | N3: =_xlfn.XLOOKUP(C3,Dados!$C$3:$C$329,Dados!$L$3:$L$329,"") -> 5 | O3: =_xlfn.XLOOKUP(C3,Dados!$C$3:$C$329,Dados!$M$3:$M$329,"") -> 0.69510031 | P3: =_xlfn.XLOOKUP(C3,Dados!$C$3:$C$329,Dados!$N$3:$N$329,"") -> 0.66462243 | Q3: =_xlfn.XLOOKUP(C3,Dados!$C$3:$C$329,Dados!$O$3:$O$329,"") -> 0.63967399 | R3: =_xlfn.XLOOKUP(C3,Dados!$C$3:$C$329,Dados!$P$3:$P$329,"") -> 0.61810946 | S3: =_xlfn.XLOOKUP(C3,Dados!$C$3:$C$329,Dados!$Q$3:$Q$329,"") -> 0.63968253 | T3: =_xlfn.XLOOKUP(C3,Dados!$C$3:$C$329,Dados!$R$3:$R$329,"") -> 0.77192735 | U3: =_xlfn.XLOOKUP(C3,Dados!$C$3:$C$329,Dados!$S$3:$S$329,"") -> 0.91070258 | V3: =_xlfn.XLOOKUP(C3,Dados!$C$3:$C$329,Dados!$T$3:$T$329,"") -> 1556.1984 | W3: =_xlfn.XLOOKUP(C3,Dados!$C$3:$C$329,Dados!$U$3:$U$329,"") -> 1312.0591 | X3: =_xlfn.XLOOKUP(C3,Dados!$C$3:$C$329,Dados!$V$3:$V$329,"") -> 1115.0723 | Y3: =_xlfn.XLOOKUP(C3,Dados!$C$3:$C$329,Dados!$W$3:$W$329,"") -> 892.45993 | Z3: =_xlfn.XLOOKUP(C3,Dados!$C$3:$C$329,Dados!$X$3:$X$329,"") -> 870.77725 | AF3: 0.026221197 | AG3: 0.022960779 | AH3: 0.024909386 | AI3: 0.028711454 | AJ3: 0.053752128 | AK3: {=_xlfn.XLOOKUP(C3,Dados!$C$3:$C$329,Dados!$Z$3:'Dados'!$Z$329,"")} -> 10.225099 | AL3: {=_xlfn.XLOOKUP(C3,Dados!$C$3:$C$329,Dados!$AA$3:'Dados'!$AA$329,"")} -> 9.8609571 | AM3: {=_xlfn.XLOOKUP(C3,Dados!$C$3:$C$329,Dados!$AB$3:'Dados'!$AB$329,"")} -> 8.2940234 | AN3: {=_xlfn.XLOOKUP(C3,Dados!$C$3:$C$329,Dados!$AC$3:'Dados'!$AC$329,"")} -> 6.3140936 | AO3: {=_xlfn.XLOOKUP(C3,Dados!$C$3:$C$329,Dados!$AD$3:'Dados'!$AD$329,"")} -> 5.672638
A4: 20 | B4: Consórcio Público Intermunicipal de Saúde do Alto Paranaíba - CISALP | C4: 02.319.394/0001-70 | D4: Minas Gerais | E4: Sudeste | F4: =_xlfn.XLOOKUP(C4,Dados!$C$3:$C$329,Dados!$D$3:$D$329,"") -> 26 | G4: =_xlfn.XLOOKUP(C4,Dados!$C$3:$C$329,Dados!$E$3:$E$329,"") -> 414724 | H4: =_xlfn.XLOOKUP(C4,Dados!$C$3:$C$329,Dados!$F$3:$F$329,"") -> 407151 | I4: =_xlfn.XLOOKUP(C4,Dados!$C$3:$C$329,Dados!$G$3:$G$329,"") -> 399578 | J4: =_xlfn.XLOOKUP(C4,Dados!$C$3:$C$329,Dados!$H$3:$H$329,"") -> 392005 | K4: =_xlfn.XLOOKUP(C4,Dados!$C$3:$C$329,Dados!$I$3:$I$329,"") -> 389962 | L4: =_xlfn.XLOOKUP(C4,Dados!$C$3:$C$329,Dados!$J$3:$J$329,"") -> 21 | M4: =_xlfn.XLOOKUP(C4,Dados!$C$3:$C$329,Dados!$K$3:$K$329,"") -> Sudeste | N4: =_xlfn.XLOOKUP(C4,Dados!$C$3:$C$329,Dados!$L$3:$L$329,"") -> 3 | O4: =_xlfn.XLOOKUP(C4,Dados!$C$3:$C$329,Dados!$M$3:$M$329,"") -> 0.73456061 | P4: =_xlfn.XLOOKUP(C4,Dados!$C$3:$C$329,Dados!$N$3:$N$329,"") -> 0.72957273 | Q4: =_xlfn.XLOOKUP(C4,Dados!$C$3:$C$329,Dados!$O$3:$O$329,"") -> 0.6998796 | R4: =_xlfn.XLOOKUP(C4,Dados!$C$3:$C$329,Dados!$P$3:$P$329,"") -> 0.67740975 | S4: =_xlfn.XLOOKUP(C4,Dados!$C$3:$C$329,Dados!$Q$3:$Q$329,"") -> 0.8325534 | T4: =_xlfn.XLOOKUP(C4,Dados!$C$3:$C$329,Dados!$R$3:$R$329,"") -> 0.86673089 | U4: =_xlfn.XLOOKUP(C4,Dados!$C$3:$C$329,Dados!$S$3:$S$329,"") -> 0.91337346 | V4: =_xlfn.XLOOKUP(C4,Dados!$C$3:$C$329,Dados!$T$3:$T$329,"") -> 2137.3426 | W4: =_xlfn.XLOOKUP(C4,Dados!$C$3:$C$329,Dados!$U$3:$U$329,"") -> 1904.0858 | X4: =_xlfn.XLOOKUP(C4,Dados!$C$3:$C$329,Dados!$V$3:$V$329,"") -> 1650.0873 | Y4: =_xlfn.XLOOKUP(C4,Dados!$C$3:$C$329,Dados!$W$3:$W$329,"") -> 1340.1078 | Z4: =_xlfn.XLOOKUP(C4,Dados!$C$3:$C$329,Dados!$X$3:$X$329,"") -> 1181.3131 | AF4: 0.17331953 | AG4: 0.09685608 | AH4: 0.063488302 | AI4: 0.065806083 | AJ4: 0.093623651 | AK4: {=_xlfn.XLOOKUP(C4,Dados!$C$3:$C$329,Dados!$Z$3:'Dados'!$Z$329,"")} -> 14.921425 | AL4: {=_xlfn.XLOOKUP(C4,Dados!$C$3:$C$329,Dados!$AA$3:'Dados'!$AA$329,"")} -> 11.711201 | AM4: {=_xlfn.XLOOKUP(C4,Dados!$C$3:$C$329,Dados!$AB$3:'Dados'!$AB$329,"")} -> 10.328749 | AN4: {=_xlfn.XLOOKUP(C4,Dados!$C$3:$C$329,Dados!$AC$3:'Dados'!$AC$329,"")} -> 14.223847 | AO4: {=_xlfn.XLOOKUP(C4,Dados!$C$3:$C$329,Dados!$AD$3:'Dados'!$AD$329,"")} -> 9.7380899
A5: 21 | B5: Consórcio Intermunicipal de Saúde da Mata Leste CISLESTE | C5: 00.738.236/0001-20 | D5: Minas Gerais | E5: Sudeste | F5: =_xlfn.XLOOKUP(C5,Dados!$C$3:$C$329,Dados!$D$3:$D$329,"") -> 29 | G5: =_xlfn.XLOOKUP(C5,Dados!$C$3:$C$329,Dados!$E$3:$E$329,"") -> 245780 | H5: =_xlfn.XLOOKUP(C5,Dados!$C$3:$C$329,Dados!$F$3:$F$329,"") -> 247291.67 | I5: =_xlfn.XLOOKUP(C5,Dados!$C$3:$C$329,Dados!$G$3:$G$329,"") -> 248803.33 | J5: =_xlfn.XLOOKUP(C5,Dados!$C$3:$C$329,Dados!$H$3:$H$329,"") -> 250315 | K5: =_xlfn.XLOOKUP(C5,Dados!$C$3:$C$329,Dados!$I$3:$I$329,"") -> 249466 | L5: =_xlfn.XLOOKUP(C5,Dados!$C$3:$C$329,Dados!$J$3:$J$329,"") -> 18 | M5: =_xlfn.XLOOKUP(C5,Dados!$C$3:$C$329,Dados!$K$3:$K$329,"") -> Sudeste | N5: =_xlfn.XLOOKUP(C5,Dados!$C$3:$C$329,Dados!$L$3:$L$329,"") -> 4 | O5: =_xlfn.XLOOKUP(C5,Dados!$C$3:$C$329,Dados!$M$3:$M$329,"") -> 0.66671315 | P5: =_xlfn.XLOOKUP(C5,Dados!$C$3:$C$329,Dados!$N$3:$N$329,"") -> 0.63322455 | Q5: =_xlfn.XLOOKUP(C5,Dados!$C$3:$C$329,Dados!$O$3:$O$329,"") -> 0.60292738 | R5: =_xlfn.XLOOKUP(C5,Dados!$C$3:$C$329,Dados!$P$3:$P$329,"") -> 0.58126692 | S5: =_xlfn.XLOOKUP(C5,Dados!$C$3:$C$329,Dados!$Q$3:$Q$329,"") -> 0.76760533 | T5: =_xlfn.XLOOKUP(C5,Dados!$C$3:$C$329,Dados!$R$3:$R$329,"") -> 0.80088567 | U5: =_xlfn.XLOOKUP(C5,Dados!$C$3:$C$329,Dados!$S$3:$S$329,"") -> 0.88212909 | V5: =_xlfn.XLOOKUP(C5,Dados!$C$3:$C$329,Dados!$T$3:$T$329,"") -> 2281.3406 | W5: =_xlfn.XLOOKUP(C5,Dados!$C$3:$C$329,Dados!$U$3:$U$329,"") -> 1348.7827 | X5: =_xlfn.XLOOKUP(C5,Dados!$C$3:$C$329,Dados!$V$3:$V$329,"") -> 1083.8735 | Y5: =_xlfn.XLOOKUP(C5,Dados!$C$3:$C$329,Dados!$W$3:$W$329,"") -> 952.88239 | Z5: =_xlfn.XLOOKUP(C5,Dados!$C$3:$C$329,Dados!$X$3:$X$329,"") -> 810.80912 | AF5: 0 | AG5: 0 | AH5: 0 | AI5: 0 | AJ5: 0 | AK5: {=_xlfn.XLOOKUP(C5,Dados!$C$3:$C$329,Dados!$Z$3:'Dados'!$Z$329,"")} -> 11.394674 | AL5: {=_xlfn.XLOOKUP(C5,Dados!$C$3:$C$329,Dados!$AA$3:'Dados'!$AA$329,"")} -> 2.4402925 | AM5: {=_xlfn.XLOOKUP(C5,Dados!$C$3:$C$329,Dados!$AB$3:'Dados'!$AB$329,"")} -> 1.6787838 | AN5: {=_xlfn.XLOOKUP(C5,Dados!$C$3:$C$329,Dados!$AC$3:'Dados'!$AC$329,"")} -> 1.3645886 | AO5: {=_xlfn.XLOOKUP(C5,Dados!$C$3:$C$329,Dados!$AD$3:'Dados'!$AD$329,"")} -> 2.5606536
A6: 28 | B6: Consórcio Intermunicipal de Saúde da Microrregião de Viçosa CISMIV | C6: 02.326.365/0001-36 | D6: Minas Gerais | E6: Sudeste | F6: =_xlfn.XLOOKUP(C6,Dados!$C$3:$C$329,Dados!$D$3:$D$329,"") -> 27 | G6: =_xlfn.XLOOKUP(C6,Dados!$C$3:$C$329,Dados!$E$3:$E$329,"") -> 145788 | H6: =_xlfn.XLOOKUP(C6,Dados!$C$3:$C$329,Dados!$F$3:$F$329,"") -> 146226 | I6: =_xlfn.XLOOKUP(C6,Dados!$C$3:$C$329,Dados!$G$3:$G$329,"") -> 146664 | J6: =_xlfn.XLOOKUP(C6,Dados!$C$3:$C$329,Dados!$H$3:$H$329,"") -> 147102 | K6: =_xlfn.XLOOKUP(C6,Dados!$C$3:$C$329,Dados!$I$3:$I$329,"") -> 146508 | L6: =_xlfn.XLOOKUP(C6,Dados!$C$3:$C$329,Dados!$J$3:$J$329,"") -> 10 | M6: =_xlfn.XLOOKUP(C6,Dados!$C$3:$C$329,Dados!$K$3:$K$329,"") -> Sudeste | N6: =_xlfn.XLOOKUP(C6,Dados!$C$3:$C$329,Dados!$L$3:$L$329,"") -> 2 | O6: =_xlfn.XLOOKUP(C6,Dados!$C$3:$C$329,Dados!$M$3:$M$329,"") -> 0.52408056 | P6: =_xlfn.XLOOKUP(C6,Dados!$C$3:$C$329,Dados!$N$3:$N$329,"") -> 0.53101865 | Q6: =_xlfn.XLOOKUP(C6,Dados!$C$3:$C$329,Dados!$O$3:$O$329,"") -> 0.51496867 | R6: =_xlfn.XLOOKUP(C6,Dados!$C$3:$C$329,Dados!$P$3:$P$329,"") -> 0.50601852 | S6: =_xlfn.XLOOKUP(C6,Dados!$C$3:$C$329,Dados!$Q$3:$Q$329,"") -> 0.76443516 | T6: =_xlfn.XLOOKUP(C6,Dados!$C$3:$C$329,Dados!$R$3:$R$329,"") -> 0.78975905 | U6: =_xlfn.XLOOKUP(C6,Dados!$C$3:$C$329,Dados!$S$3:$S$329,"") -> 0.9117176 | V6: =_xlfn.XLOOKUP(C6,Dados!$C$3:$C$329,Dados!$T$3:$T$329,"") -> 1999.5901 | W6: =_xlfn.XLOOKUP(C6,Dados!$C$3:$C$329,Dados!$U$3:$U$329,"") -> 1470.9841 | X6: =_xlfn.XLOOKUP(C6,Dados!$C$3:$C$329,Dados!$V$3:$V$329,"") -> 1409.3357 | Y6: =_xlfn.XLOOKUP(C6,Dados!$C$3:$C$329,Dados!$W$3:$W$329,"") -> 1240.8729 | Z6: =_xlfn.XLOOKUP(C6,Dados!$C$3:$C$329,Dados!$X$3:$X$329,"") -> 1125.3003 | AF6: 0.069677619 | AG6: 0.11417748 | AH6: 0.11934932 | AI6: 0.12941992 | AJ6: 0.19019746 | AK6: {=_xlfn.XLOOKUP(C6,Dados!$C$3:$C$329,Dados!$Z$3:'Dados'!$Z$329,"")} -> 4.8090309 | AL6: {=_xlfn.XLOOKUP(C6,Dados!$C$3:$C$329,Dados!$AA$3:'Dados'!$AA$329,"")} -> 2.2467892 | AM6: {=_xlfn.XLOOKUP(C6,Dados!$C$3:$C$329,Dados!$AB$3:'Dados'!$AB$329,"")} -> 2.3648885 | AN6: {=_xlfn.XLOOKUP(C6,Dados!$C$3:$C$329,Dados!$AC$3:'Dados'!$AC$329,"")} -> 2.2308874 | AO6: {=_xlfn.XLOOKUP(C6,Dados!$C$3:$C$329,Dados!$AD$3:'Dados'!$AD$329,"")} -> 1.7440208
A7: 29 | B7: Consórcio Intermunicipal de Saúde do Alto das Vertentes - CISALV | C7: 02.334.933/0001-40 | D7: Minas Gerais | E7: Sudeste | F7: =_xlfn.XLOOKUP(C7,Dados!$C$3:$C$329,Dados!$D$3:$D$329,"") -> 27 | G7: =_xlfn.XLOOKUP(C7,Dados!$C$3:$C$329,Dados!$E$3:$E$329,"") -> 269765 | H7: =_xlfn.XLOOKUP(C7,Dados!$C$3:$C$329,Dados!$F$3:$F$329,"") -> 273212.33 | I7: =_xlfn.XLOOKUP(C7,Dados!$C$3:$C$329,Dados!$G$3:$G$329,"") -> 276659.67 | J7: =_xlfn.XLOOKUP(C7,Dados!$C$3:$C$329,Dados!$H$3:$H$329,"") -> 280107 | K7: =_xlfn.XLOOKUP(C7,Dados!$C$3:$C$329,Dados!$I$3:$I$329,"") -> 279154 | L7: =_xlfn.XLOOKUP(C7,Dados!$C$3:$C$329,Dados!$J$3:$J$329,"") -> 21 | M7: =_xlfn.XLOOKUP(C7,Dados!$C$3:$C$329,Dados!$K$3:$K$329,"") -> Sudeste | N7: =_xlfn.XLOOKUP(C7,Dados!$C$3:$C$329,Dados!$L$3:$L$329,"") -> 3 | O7: =_xlfn.XLOOKUP(C7,Dados!$C$3:$C$329,Dados!$M$3:$M$329,"") -> 0.6644703 | P7: =_xlfn.XLOOKUP(C7,Dados!$C$3:$C$329,Dados!$N$3:$N$329,"") -> 0.65044136 | Q7: =_xlfn.XLOOKUP(C7,Dados!$C$3:$C$329,Dados!$O$3:$O$329,"") -> 0.62029869 | R7: =_xlfn.XLOOKUP(C7,Dados!$C$3:$C$329,Dados!$P$3:$P$329,"") -> 0.61296011 | S7: =_xlfn.XLOOKUP(C7,Dados!$C$3:$C$329,Dados!$Q$3:$Q$329,"") -> 0.72726548 | T7: =_xlfn.XLOOKUP(C7,Dados!$C$3:$C$329,Dados!$R$3:$R$329,"") -> 0.81197609 | U7: =_xlfn.XLOOKUP(C7,Dados!$C$3:$C$329,Dados!$S$3:$S$329,"") -> 0.90007772 | V7: =_xlfn.XLOOKUP(C7,Dados!$C$3:$C$329,Dados!$T$3:$T$329,"") -> 2169.1334 | W7: =_xlfn.XLOOKUP(C7,Dados!$C$3:$C$329,Dados!$U$3:$U$329,"") -> 1670.599 | X7: =_xlfn.XLOOKUP(C7,Dados!$C$3:$C$329,Dados!$V$3:$V$329,"") -> 1465.6304 | Y7: =_xlfn.XLOOKUP(C7,Dados!$C$3:$C$329,Dados!$W$3:$W$329,"") -> 1248.9782 | Z7: =_xlfn.XLOOKUP(C7,Dados!$C$3:$C$329,Dados!$X$3:$X$329,"") -> 1058.5287 | AF7: 0.043808758 | AG7: 0.038604255 | AH7: 0.044972003 | AI7: 0.054324279 | AJ7: 0.0658808 | AK7: {=_xlfn.XLOOKUP(C7,Dados!$C$3:$C$329,Dados!$Z$3:'Dados'!$Z$329,"")} -> 14.958201 | AL7: {=_xlfn.XLOOKUP(C7,Dados!$C$3:$C$329,Dados!$AA$3:'Dados'!$AA$329,"")} -> 9.3319689 | AM7: {=_xlfn.XLOOKUP(C7,Dados!$C$3:$C$329,Dados!$AB$3:'Dados'!$AB$329,"")} -> 6.9743162 | AN7: {=_xlfn.XLOOKUP(C7,Dados!$C$3:$C$329,Dados!$AC$3:'Dados'!$AC$329,"")} -> 5.4564577 | AO7: {=_xlfn.XLOOKUP(C7,Dados!$C$3:$C$329,Dados!$AD$3:'Dados'!$AD$329,"")} -> 5.3093705
A8: 31 | B8: Consorcio Intermunicipal de Especialidades - CIESP | C8: 07.356.999/0001-55 | D8: Minas Gerais | E8: Sudeste | F8: =_xlfn.XLOOKUP(C8,Dados!$C$3:$C$329,Dados!$D$3:$D$329,"") -> 19 | G8: =_xlfn.XLOOKUP(C8,Dados!$C$3:$C$329,Dados!$E$3:$E$329,"") -> 222172 | H8: =_xlfn.XLOOKUP(C8,Dados!$C$3:$C$329,Dados!$F$3:$F$329,"") -> 220297.33 | I8: =_xlfn.XLOOKUP(C8,Dados!$C$3:$C$329,Dados!$G$3:$G$329,"") -> 218422.67 | J8: =_xlfn.XLOOKUP(C8,Dados!$C$3:$C$329,Dados!$H$3:$H$329,"") -> 216548 | K8: =_xlfn.XLOOKUP(C8,Dados!$C$3:$C$329,Dados!$I$3:$I$329,"") -> 215323 | L8: =_xlfn.XLOOKUP(C8,Dados!$C$3:$C$329,Dados!$J$3:$J$329,"") -> 12 | M8: =_xlfn.XLOOKUP(C8,Dados!$C$3:$C$329,Dados!$K$3:$K$329,"") -> Sudeste | N8: =_xlfn.XLOOKUP(C8,Dados!$C$3:$C$329,Dados!$L$3:$L$329,"") -> 3 | O8: =_xlfn.XLOOKUP(C8,Dados!$C$3:$C$329,Dados!$M$3:$M$329,"") -> 0.7581806 | P8: =_xlfn.XLOOKUP(C8,Dados!$C$3:$C$329,Dados!$N$3:$N$329,"") -> 0.72932984 | Q8: =_xlfn.XLOOKUP(C8,Dados!$C$3:$C$329,Dados!$O$3:$O$329,"") -> 0.71287227 | R8: =_xlfn.XLOOKUP(C8,Dados!$C$3:$C$329,Dados!$P$3:$P$329,"") -> 0.69677622 | S8: =_xlfn.XLOOKUP(C8,Dados!$C$3:$C$329,Dados!$Q$3:$Q$329,"") -> 0.92302218 | T8: =_xlfn.XLOOKUP(C8,Dados!$C$3:$C$329,Dados!$R$3:$R$329,"") -> 0.9470063 | U8: =_xlfn.XLOOKUP(C8,Dados!$C$3:$C$329,Dados!$S$3:$S$329,"") -> 0.97906319 | V8: =_xlfn.XLOOKUP(C8,Dados!$C$3:$C$329,Dados!$T$3:$T$329,"") -> 2687.3098 | W8: =_xlfn.XLOOKUP(C8,Dados!$C$3:$C$329,Dados!$U$3:$U$329,"") -> 2137.6043 | X8: =_xlfn.XLOOKUP(C8,Dados!$C$3:$C$329,Dados!$V$3:$V$329,"") -> 1709.4515 | Y8: =_xlfn.XLOOKUP(C8,Dados!$C$3:$C$329,Dados!$W$3:$W$329,"") -> 1475.8375 | Z8: =_xlfn.XLOOKUP(C8,Dados!$C$3:$C$329,Dados!$X$3:$X$329,"") -> 1538.4031 | AF8: 0.11487929 | AG8: 0.15125953 | AH8: 0.19195704 | AI8: 0.20859351 | AJ8: 0.26024391 | AK8: {=_xlfn.XLOOKUP(C8,Dados!$C$3:$C$329,Dados!$Z$3:'Dados'!$Z$329,"")} -> 15.439902 | AL8: {=_xlfn.XLOOKUP(C8,Dados!$C$3:$C$329,Dados!$AA$3:'Dados'!$AA$329,"")} -> 13.690447 | AM8: {=_xlfn.XLOOKUP(C8,Dados!$C$3:$C$329,Dados!$AB$3:'Dados'!$AB$329,"")} -> 14.649936 | AN8: {=_xlfn.XLOOKUP(C8,Dados!$C$3:$C$329,Dados!$AC$3:'Dados'!$AC$329,"")} -> 12.691228 | AO8: {=_xlfn.XLOOKUP(C8,Dados!$C$3:$C$329,Dados!$AD$3:'Dados'!$AD$329,"")} -> 11.04092
A9: 33 | B9: Consórcio Público Intermunicipal de Saúde do Triângulo Mineiro CISTM | C9: 18.151.467/0001-06 | D9: Minas Gerais | E9: Sudeste | F9: =_xlfn.XLOOKUP(C9,Dados!$C$3:$C$329,Dados!$D$3:$D$329,"") -> 11 | G9: =_xlfn.XLOOKUP(C9,Dados!$C$3:$C$329,Dados!$E$3:$E$329,"") -> 481897 | H9: =_xlfn.XLOOKUP(C9,Dados!$C$3:$C$329,Dados!$F$3:$F$329,"") -> 480386.67 | I9: =_xlfn.XLOOKUP(C9,Dados!$C$3:$C$329,Dados!$G$3:$G$329,"") -> 478876.33 | J9: =_xlfn.XLOOKUP(C9,Dados!$C$3:$C$329,Dados!$H$3:$H$329,"") -> 477366 | K9: =_xlfn.XLOOKUP(C9,Dados!$C$3:$C$329,Dados!$I$3:$I$329,"") -> 475413 | L9: =_xlfn.XLOOKUP(C9,Dados!$C$3:$C$329,Dados!$J$3:$J$329,"") -> 22 | M9: =_xlfn.XLOOKUP(C9,Dados!$C$3:$C$329,Dados!$K$3:$K$329,"") -> Sudeste | N9: =_xlfn.XLOOKUP(C9,Dados!$C$3:$C$329,Dados!$L$3:$L$329,"") -> 2 | O9: =_xlfn.XLOOKUP(C9,Dados!$C$3:$C$329,Dados!$M$3:$M$329,"") -> 0.71612996 | P9: =_xlfn.XLOOKUP(C9,Dados!$C$3:$C$329,Dados!$N$3:$N$329,"") -> 0.69920697 | Q9: =_xlfn.XLOOKUP(C9,Dados!$C$3:$C$329,Dados!$O$3:$O$329,"") -> 0.67172318 | R9: =_xlfn.XLOOKUP(C9,Dados!$C$3:$C$329,Dados!$P$3:$P$329,"") -> 0.65311832 | S9: =_xlfn.XLOOKUP(C9,Dados!$C$3:$C$329,Dados!$Q$3:$Q$329,"") -> 0.84101671 | T9: =_xlfn.XLOOKUP(C9,Dados!$C$3:$C$329,Dados!$R$3:$R$329,"") -> 0.87508797 | U9: =_xlfn.XLOOKUP(C9,Dados!$C$3:$C$329,Dados!$S$3:$S$329,"") -> 0.92191571 | V9: =_xlfn.XLOOKUP(C9,Dados!$C$3:$C$329,Dados!$T$3:$T$329,"") -> 2255.4274 | W9: =_xlfn.XLOOKUP(C9,Dados!$C$3:$C$329,Dados!$U$3:$U$329,"") -> 1823.7467 | X9: =_xlfn.XLOOKUP(C9,Dados!$C$3:$C$329,Dados!$V$3:$V$329,"") -> 1536.8933 | Y9: =_xlfn.XLOOKUP(C9,Dados!$C$3:$C$329,Dados!$W$3:$W$329,"") -> 1314.981 | Z9: =_xlfn.XLOOKUP(C9,Dados!$C$3:$C$329,Dados!$X$3:$X$329,"") -> 1097.1187 | AF9: #DIV/0! | AG9: #DIV/0! | AH9: #DIV/0! | AI9: 0.061396425 | AJ9: 0.076463768 | AK9: {=_xlfn.XLOOKUP(C9,Dados!$C$3:$C$329,Dados!$Z$3:'Dados'!$Z$329,"")} -> 15.444942 | AL9: {=_xlfn.XLOOKUP(C9,Dados!$C$3:$C$329,Dados!$AA$3:'Dados'!$AA$329,"")} -> 12.262455 | AM9: {=_xlfn.XLOOKUP(C9,Dados!$C$3:$C$329,Dados!$AB$3:'Dados'!$AB$329,"")} -> 8.3966188 | AN9: {=_xlfn.XLOOKUP(C9,Dados!$C$3:$C$329,Dados!$AC$3:'Dados'!$AC$329,"")} -> 6.8531357 | AO9: {=_xlfn.XLOOKUP(C9,Dados!$C$3:$C$329,Dados!$AD$3:'Dados'!$AD$329,"")} -> 8.6757072
A10: 36 | B10: Consórcio Intermunicipal de Saúde da Rede de Urgência e Emergência da Região Ampliada do Noroeste CISREUNO | C10: 20.433.216/0001-58 | D10: Minas Gerais | E10: Sudeste | F10: =_xlfn.XLOOKUP(C10,Dados!$C$3:$C$329,Dados!$D$3:$D$329,"") -> 10 | G10: =_xlfn.XLOOKUP(C10,Dados!$C$3:$C$329,Dados!$E$3:$E$329,"") -> 741869 | H10: =_xlfn.XLOOKUP(C10,Dados!$C$3:$C$329,Dados!$F$3:$F$329,"") -> 732635 | I10: =_xlfn.XLOOKUP(C10,Dados!$C$3:$C$329,Dados!$G$3:$G$329,"") -> 723401 | J10: =_xlfn.XLOOKUP(C10,Dados!$C$3:$C$329,Dados!$H$3:$H$329,"") -> 714167 | K10: =_xlfn.XLOOKUP(C10,Dados!$C$3:$C$329,Dados!$I$3:$I$329,"") -> 710130 | L10: =_xlfn.XLOOKUP(C10,Dados!$C$3:$C$329,Dados!$J$3:$J$329,"") -> 33 | M10: =_xlfn.XLOOKUP(C10,Dados!$C$3:$C$329,Dados!$K$3:$K$329,"") -> Sudeste | N10: =_xlfn.XLOOKUP(C10,Dados!$C$3:$C$329,Dados!$L$3:$L$329,"") -> 3 | O10: =_xlfn.XLOOKUP(C10,Dados!$C$3:$C$329,Dados!$M$3:$M$329,"") -> 0.72014027 | P10: =_xlfn.XLOOKUP(C10,Dados!$C$3:$C$329,Dados!$N$3:$N$329,"") -> 0.70657689 | Q10: =_xlfn.XLOOKUP(C10,Dados!$C$3:$C$329,Dados!$O$3:$O$329,"") -> 0.68091031 | R10: =_xlfn.XLOOKUP(C10,Dados!$C$3:$C$329,Dados!$P$3:$P$329,"") -> 0.65298746 | S10: =_xlfn.XLOOKUP(C10,Dados!$C$3:$C$329,Dados!$Q$3:$Q$329,"") -> 0.74286126 | T10: =_xlfn.XLOOKUP(C10,Dados!$C$3:$C$329,Dados!$R$3:$R$329,"") -> 0.82005461 | U10: =_xlfn.XLOOKUP(C10,Dados!$C$3:$C$329,Dados!$S$3:$S$329,"") -> 0.88223314 | V10: =_xlfn.XLOOKUP(C10,Dados!$C$3:$C$329,Dados!$T$3:$T$329,"") -> 2160.5564 | W10: =_xlfn.XLOOKUP(C10,Dados!$C$3:$C$329,Dados!$U$3:$U$329,"") -> 1948.135 | X10: =_xlfn.XLOOKUP(C10,Dados!$C$3:$C$329,Dados!$V$3:$V$329,"") -> 1650.5337 | Y10: =_xlfn.XLOOKUP(C10,Dados!$C$3:$C$329,Dados!$W$3:$W$329,"") -> 1369.5763 | Z10: =_xlfn.XLOOKUP(C10,Dados!$C$3:$C$329,Dados!$X$3:$X$329,"") -> 1188.1849 | AF10: 0.8155101 | AG10: 0.83499415 | AH10: 0.15381227 | AI10: #DIV/0! | AJ10: #DIV/0! | AK10: {=_xlfn.XLOOKUP(C10,Dados!$C$3:$C$329,Dados!$Z$3:'Dados'!$Z$329,"")} -> 15.03655 | AL10: {=_xlfn.XLOOKUP(C10,Dados!$C$3:$C$329,Dados!$AA$3:'Dados'!$AA$329,"")} -> 11.443091 | AM10: {=_xlfn.XLOOKUP(C10,Dados!$C$3:$C$329,Dados!$AB$3:'Dados'!$AB$329,"")} -> 11.339539 | AN10: {=_xlfn.XLOOKUP(C10,Dados!$C$3:$C$329,Dados!$AC$3:'Dados'!$AC$329,"")} -> 11.441906 | AO10: {=_xlfn.XLOOKUP(C10,Dados!$C$3:$C$329,Dados!$AD$3:'Dados'!$AD$329,"")} -> 9.7204441
A11: 37 | B11: Consórcio Intermunicipal Multifinalitário do Vale de Paraibuna - CIMPAR | C11: 21.565.740/0001-45 | D11: Minas Gerais | E11: Sudeste | F11: =_xlfn.XLOOKUP(C11,Dados!$C$3:$C$329,Dados!$D$3:$D$329,"") -> 10 | G11: =_xlfn.XLOOKUP(C11,Dados!$C$3:$C$329,Dados!$E$3:$E$329,"") -> 684595 | H11: =_xlfn.XLOOKUP(C11,Dados!$C$3:$C$329,Dados!$F$3:$F$329,"") -> 688660.67 | I11: =_xlfn.XLOOKUP(C11,Dados!$C$3:$C$329,Dados!$G$3:$G$329,"") -> 692726.33 | J11: =_xlfn.XLOOKUP(C11,Dados!$C$3:$C$329,Dados!$H$3:$H$329,"") -> 696792 | K11: =_xlfn.XLOOKUP(C11,Dados!$C$3:$C$329,Dados!$I$3:$I$329,"") -> 692272 | L11: =_xlfn.XLOOKUP(C11,Dados!$C$3:$C$329,Dados!$J$3:$J$329,"") -> 17 | M11: =_xlfn.XLOOKUP(C11,Dados!$C$3:$C$329,Dados!$K$3:$K$329,"") -> Sudeste | N11: =_xlfn.XLOOKUP(C11,Dados!$C$3:$C$329,Dados!$L$3:$L$329,"") -> 21 | O11: =_xlfn.XLOOKUP(C11,Dados!$C$3:$C$329,Dados!$M$3:$M$329,"") -> 0.72124588 | P11: =_xlfn.XLOOKUP(C11,Dados!$C$3:$C$329,Dados!$N$3:$N$329,"") -> 0.69254276 | Q11: =_xlfn.XLOOKUP(C11,Dados!$C$3:$C$329,Dados!$O$3:$O$329,"") -> 0.67192903 | R11: =_xlfn.XLOOKUP(C11,Dados!$C$3:$C$329,Dados!$P$3:$P$329,"") -> 0.67184266 | S11: =_xlfn.XLOOKUP(C11,Dados!$C$3:$C$329,Dados!$Q$3:$Q$329,"") -> 0.90729025 | T11: =_xlfn.XLOOKUP(C11,Dados!$C$3:$C$329,Dados!$R$3:$R$329,"") -> 0.94095576 | U11: =_xlfn.XLOOKUP(C11,Dados!$C$3:$C$329,Dados!$S$3:$S$329,"") -> 0.98273728 | V11: =_xlfn.XLOOKUP(C11,Dados!$C$3:$C$329,Dados!$T$3:$T$329,"") -> 2029.5979 | W11: =_xlfn.XLOOKUP(C11,Dados!$C$3:$C$329,Dados!$U$3:$U$329,"") -> 1538.4237 | X11: =_xlfn.XLOOKUP(C11,Dados!$C$3:$C$329,Dados!$V$3:$V$329,"") -> 1365.4828 | Y11: =_xlfn.XLOOKUP(C11,Dados!$C$3:$C$329,Dados!$W$3:$W$329,"") -> 1378.9161 | Z11: =_xlfn.XLOOKUP(C11,Dados!$C$3:$C$329,Dados!$X$3:$X$329,"") -> 1212.4931 | AF11: 0.044889093 | AG11: 0.055106257 | AH11: #DIV/0! | AI11: #DIV/0! | AJ11: #DIV/0! | AK11: {=_xlfn.XLOOKUP(C11,Dados!$C$3:$C$329,Dados!$Z$3:'Dados'!$Z$329,"")} -> 13.745612 | AL11: {=_xlfn.XLOOKUP(C11,Dados!$C$3:$C$329,Dados!$AA$3:'Dados'!$AA$329,"")} -> 11.525023 | AM11: {=_xlfn.XLOOKUP(C11,Dados!$C$3:$C$329,Dados!$AB$3:'Dados'!$AB$329,"")} -> 11.814195 | AN11: {=_xlfn.XLOOKUP(C11,Dados!$C$3:$C$329,Dados!$AC$3:'Dados'!$AC$329,"")} -> 10.451064 | AO11: {=_xlfn.XLOOKUP(C11,Dados!$C$3:$C$329,Dados!$AD$3:'Dados'!$AD$329,"")} -> 8.2462168
A12: 39 | B12: Consórcio Intermunicipal de Saúde do Médio Espinhaço CISAME | C12: 31.974.558/0001-00 | D12: Minas Gerais | E12: Sudeste | F12: =_xlfn.XLOOKUP(C12,Dados!$C$3:$C$329,Dados!$D$3:$D$329,"") -> 6 | G12: =_xlfn.XLOOKUP(C12,Dados!$C$3:$C$329,Dados!$E$3:$E$329,"") -> 33627 | H12: =_xlfn.XLOOKUP(C12,Dados!$C$3:$C$329,Dados!$F$3:$F$329,"") -> 30911 | I12: =_xlfn.XLOOKUP(C12,Dados!$C$3:$C$329,Dados!$G$3:$G$329,"") -> 28195 | J12: =_xlfn.XLOOKUP(C12,Dados!$C$3:$C$329,Dados!$H$3:$H$329,"") -> 25479 | K12: =_xlfn.XLOOKUP(C12,Dados!$C$3:$C$329,Dados!$I$3:$I$329,"") -> 25559 | L12: =_xlfn.XLOOKUP(C12,Dados!$C$3:$C$329,Dados!$J$3:$J$329,"") -> 3 | M12: =_xlfn.XLOOKUP(C12,Dados!$C$3:$C$329,Dados!$K$3:$K$329,"") -> Sudeste | N12: =_xlfn.XLOOKUP(C12,Dados!$C$3:$C$329,Dados!$L$3:$L$329,"") -> 4 | O12: =_xlfn.XLOOKUP(C12,Dados!$C$3:$C$329,Dados!$M$3:$M$329,"") -> 0.64229389 | P12: =_xlfn.XLOOKUP(C12,Dados!$C$3:$C$329,Dados!$N$3:$N$329,"") -> 0.65978765 | Q12: =_xlfn.XLOOKUP(C12,Dados!$C$3:$C$329,Dados!$O$3:$O$329,"") -> 0.64130044 | R12: =_xlfn.XLOOKUP(C12,Dados!$C$3:$C$329,Dados!$P$3:$P$329,"") -> 0.58363937 | S12: =_xlfn.XLOOKUP(C12,Dados!$C$3:$C$329,Dados!$Q$3:$Q$329,"") -> 0.58345369 | T12: =_xlfn.XLOOKUP(C12,Dados!$C$3:$C$329,Dados!$R$3:$R$329,"") -> 0.64852875 | U12: =_xlfn.XLOOKUP(C12,Dados!$C$3:$C$329,Dados!$S$3:$S$329,"") -> 0.79824167 | V12: =_xlfn.XLOOKUP(C12,Dados!$C$3:$C$329,Dados!$T$3:$T$329,"") -> 4637.2651 | W12: =_xlfn.XLOOKUP(C12,Dados!$C$3:$C$329,Dados!$U$3:$U$329,"") -> 4561.9329 | X12: =_xlfn.XLOOKUP(C12,Dados!$C$3:$C$329,Dados!$V$3:$V$329,"") -> 3660.3695 | Y12: =_xlfn.XLOOKUP(C12,Dados!$C$3:$C$329,Dados!$W$3:$W$329,"") -> 2306.8217 | Z12: =_xlfn.XLOOKUP(C12,Dados!$C$3:$C$329,Dados!$X$3:$X$329,"") -> 2348.3117 | AF12: 0.23285206 | AG12: 0.25634828 | AH12: 0.32740417 | AI12: #DIV/0! | AJ12: #DIV/0! | AK12: {=_xlfn.XLOOKUP(C12,Dados!$C$3:$C$329,Dados!$Z$3:'Dados'!$Z$329,"")} -> 32.211556 | AL12: {=_xlfn.XLOOKUP(C12,Dados!$C$3:$C$329,Dados!$AA$3:'Dados'!$AA$329,"")} -> 2.6832519 | AM12: {=_xlfn.XLOOKUP(C12,Dados!$C$3:$C$329,Dados!$AB$3:'Dados'!$AB$329,"")} -> 0.6576698 | AN12: {=_xlfn.XLOOKUP(C12,Dados!$C$3:$C$329,Dados!$AC$3:'Dados'!$AC$329,"")} -> 0.14580635 | AO12: {=_xlfn.XLOOKUP(C12,Dados!$C$3:$C$329,Dados!$AD$3:'Dados'!$AD$329,"")} -> 0.42845964
A13: 41 | B13: Consórcio Intermunicipal de Saúde do Sistema Microrregional de Saúde de São Lourenço Cis Circuito das Águas | C13: 71.203.715/0001-90 | D13: Minas Gerais | E13: Sudeste | F13: =_xlfn.XLOOKUP(C13,Dados!$C$3:$C$329,Dados!$D$3:$D$329,"") -> 30 | G13: =_xlfn.XLOOKUP(C13,Dados!$C$3:$C$329,Dados!$E$3:$E$329,"") -> 181291 | H13: =_xlfn.XLOOKUP(C13,Dados!$C$3:$C$329,Dados!$F$3:$F$329,"") -> 204109 | I13: =_xlfn.XLOOKUP(C13,Dados!$C$3:$C$329,Dados!$G$3:$G$329,"") -> 203766 | J13: =_xlfn.XLOOKUP(C13,Dados!$C$3:$C$329,Dados!$H$3:$H$329,"") -> 203423 | K13: =_xlfn.XLOOKUP(C13,Dados!$C$3:$C$329,Dados!$I$3:$I$329,"") -> 179367 | L13: =_xlfn.XLOOKUP(C13,Dados!$C$3:$C$329,Dados!$J$3:$J$329,"") -> 15 | M13: =_xlfn.XLOOKUP(C13,Dados!$C$3:$C$329,Dados!$K$3:$K$329,"") -> Sudeste | N13: =_xlfn.XLOOKUP(C13,Dados!$C$3:$C$329,Dados!$L$3:$L$329,"") -> 3 | O13: =_xlfn.XLOOKUP(C13,Dados!$C$3:$C$329,Dados!$M$3:$M$329,"") -> 0.68217748 | P13: =_xlfn.XLOOKUP(C13,Dados!$C$3:$C$329,Dados!$N$3:$N$329,"") -> 0.68772381 | Q13: =_xlfn.XLOOKUP(C13,Dados!$C$3:$C$329,Dados!$O$3:$O$329,"") -> 0.64258933 | R13: =_xlfn.XLOOKUP(C13,Dados!$C$3:$C$329,Dados!$P$3:$P$329,"") -> 0.63239537 | S13: =_xlfn.XLOOKUP(C13,Dados!$C$3:$C$329,Dados!$Q$3:$Q$329,"") -> 0.77389036 | T13: =_xlfn.XLOOKUP(C13,Dados!$C$3:$C$329,Dados!$R$3:$R$329,"") -> 0.83255165 | U13: =_xlfn.XLOOKUP(C13,Dados!$C$3:$C$329,Dados!$S$3:$S$329,"") -> 0.95092061 | V13: =_xlfn.XLOOKUP(C13,Dados!$C$3:$C$329,Dados!$T$3:$T$329,"") -> 1625.0679 | W13: =_xlfn.XLOOKUP(C13,Dados!$C$3:$C$329,Dados!$U$3:$U$329,"") -> 1356.5362 | X13: =_xlfn.XLOOKUP(C13,Dados!$C$3:$C$329,Dados!$V$3:$V$329,"") -> 1161.4539 | Y13: =_xlfn.XLOOKUP(C13,Dados!$C$3:$C$329,Dados!$W$3:$W$329,"") -> 976.90617 | Z13: =_xlfn.XLOOKUP(C13,Dados!$C$3:$C$329,Dados!$X$3:$X$329,"") -> 850.94158 | AF13: 0.098188462 | AG13: 0.11922299 | AH13: 0.13696305 | AI13: 0.15852789 | AJ13: 0.17116484 | AK13: {=_xlfn.XLOOKUP(C13,Dados!$C$3:$C$329,Dados!$Z$3:'Dados'!$Z$329,"")} -> 15.60404 | AL13: {=_xlfn.XLOOKUP(C13,Dados!$C$3:$C$329,Dados!$AA$3:'Dados'!$AA$329,"")} -> 14.503991 | AM13: {=_xlfn.XLOOKUP(C13,Dados!$C$3:$C$329,Dados!$AB$3:'Dados'!$AB$329,"")} -> 9.1464409 | AN13: {=_xlfn.XLOOKUP(C13,Dados!$C$3:$C$329,Dados!$AC$3:'Dados'!$AC$329,"")} -> 5.9894649 | AO13: {=_xlfn.XLOOKUP(C13,Dados!$C$3:$C$329,Dados!$AD$3:'Dados'!$AD$329,"")} -> 4.9261458
A14: 53 | B14: Consórcio Intermunicipal de Desenvolvimento da Região Leste Fluminense - CONLESTE | C14: 08.932.750/0001-03 | D14: Rio de Janeiro | E14: Sudeste | F14: =_xlfn.XLOOKUP(C14,Dados!$C$3:$C$329,Dados!$D$3:$D$329,"") -> 18 | G14: =_xlfn.XLOOKUP(C14,Dados!$C$3:$C$329,Dados!$E$3:$E$329,"") -> 3411903 | H14: =_xlfn.XLOOKUP(C14,Dados!$C$3:$C$329,Dados!$F$3:$F$329,"") -> 3443825.7 | I14: =_xlfn.XLOOKUP(C14,Dados!$C$3:$C$329,Dados!$G$3:$G$329,"") -> 3475748.3 | J14: =_xlfn.XLOOKUP(C14,Dados!$C$3:$C$329,Dados!$H$3:$H$329,"") -> 3507671 | K14: =_xlfn.XLOOKUP(C14,Dados!$C$3:$C$329,Dados!$I$3:$I$329,"") -> 3479924 | L14: =_xlfn.XLOOKUP(C14,Dados!$C$3:$C$329,Dados!$J$3:$J$329,"") -> 17 | M14: =_xlfn.XLOOKUP(C14,Dados!$C$3:$C$329,Dados!$K$3:$K$329,"") -> Sudeste | N14: =_xlfn.XLOOKUP(C14,Dados!$C$3:$C$329,Dados!$L$3:$L$329,"") -> 26 | O14: =_xlfn.XLOOKUP(C14,Dados!$C$3:$C$329,Dados!$M$3:$M$329,"") -> 0.5987965 | P14: =_xlfn.XLOOKUP(C14,Dados!$C$3:$C$329,Dados!$N$3:$N$329,"") -> 0.58487979 | Q14: =_xlfn.XLOOKUP(C14,Dados!$C$3:$C$329,Dados!$O$3:$O$329,"") -> 0.5694628 | R14: =_xlfn.XLOOKUP(C14,Dados!$C$3:$C$329,Dados!$P$3:$P$329,"") -> 0.55150972 | S14: =_xlfn.XLOOKUP(C14,Dados!$C$3:$C$329,Dados!$Q$3:$Q$329,"") -> 0.71193285 | T14: =_xlfn.XLOOKUP(C14,Dados!$C$3:$C$329,Dados!$R$3:$R$329,"") -> 0.73115632 | U14: =_xlfn.XLOOKUP(C14,Dados!$C$3:$C$329,Dados!$S$3:$S$329,"") -> 0.97656443 | V14: =_xlfn.XLOOKUP(C14,Dados!$C$3:$C$329,Dados!$T$3:$T$329,"") -> 2018.6443 | W14: =_xlfn.XLOOKUP(C14,Dados!$C$3:$C$329,Dados!$U$3:$U$329,"") -> 1698.2709 | X14: =_xlfn.XLOOKUP(C14,Dados!$C$3:$C$329,Dados!$V$3:$V$329,"") -> 1382.9203 | Y14: =_xlfn.XLOOKUP(C14,Dados!$C$3:$C$329,Dados!$W$3:$W$329,"") -> 1153.0198 | Z14: =_xlfn.XLOOKUP(C14,Dados!$C$3:$C$329,Dados!$X$3:$X$329,"") -> 1021.9029 | AF14: 0.84839014 | AG14: 0.84248048 | AH14: 0.82883907 | AI14: 0.77887566 | AJ14: 0.89588678 | AK14: {=_xlfn.XLOOKUP(C14,Dados!$C$3:$C$329,Dados!$Z$3:'Dados'!$Z$329,"")} -> 21.022509 | AL14: {=_xlfn.XLOOKUP(C14,Dados!$C$3:$C$329,Dados!$AA$3:'Dados'!$AA$329,"")} -> 18.246891 | AM14: {=_xlfn.XLOOKUP(C14,Dados!$C$3:$C$329,Dados!$AB$3:'Dados'!$AB$329,"")} -> 16.245635 | AN14: {=_xlfn.XLOOKUP(C14,Dados!$C$3:$C$329,Dados!$AC$3:'Dados'!$AC$329,"")} -> 13.432322 | AO14: {=_xlfn.XLOOKUP(C14,Dados!$C$3:$C$329,Dados!$AD$3:'Dados'!$AD$329,"")} -> 11.330609
A15: 71 | B15: Consórcio Intermunicipal de Serviços da Nova Alta Paulista - CISNAP | C15: 02.655.907/0001-14 | D15: São Paulo | E15: Sudeste | F15: =_xlfn.XLOOKUP(C15,Dados!$C$3:$C$329,Dados!$D$3:$D$329,"") -> 26 | G15: =_xlfn.XLOOKUP(C15,Dados!$C$3:$C$329,Dados!$E$3:$E$329,"") -> 144913 | H15: =_xlfn.XLOOKUP(C15,Dados!$C$3:$C$329,Dados!$F$3:$F$329,"") -> 145326 | I15: =_xlfn.XLOOKUP(C15,Dados!$C$3:$C$329,Dados!$G$3:$G$329,"") -> 145739 | J15: =_xlfn.XLOOKUP(C15,Dados!$C$3:$C$329,Dados!$H$3:$H$329,"") -> 146152 | K15: =_xlfn.XLOOKUP(C15,Dados!$C$3:$C$329,Dados!$I$3:$I$329,"") -> 145349 | L15: =_xlfn.XLOOKUP(C15,Dados!$C$3:$C$329,Dados!$J$3:$J$329,"") -> 11 | M15: =_xlfn.XLOOKUP(C15,Dados!$C$3:$C$329,Dados!$K$3:$K$329,"") -> Sudeste | N15: =_xlfn.XLOOKUP(C15,Dados!$C$3:$C$329,Dados!$L$3:$L$329,"") -> 25 | O15: =_xlfn.XLOOKUP(C15,Dados!$C$3:$C$329,Dados!$M$3:$M$329,"") -> 0.76293708 | P15: =_xlfn.XLOOKUP(C15,Dados!$C$3:$C$329,Dados!$N$3:$N$329,"") -> 0.72018322 | Q15: =_xlfn.XLOOKUP(C15,Dados!$C$3:$C$329,Dados!$O$3:$O$329,"") -> 0.69467456 | R15: =_xlfn.XLOOKUP(C15,Dados!$C$3:$C$329,Dados!$P$3:$P$329,"") -> 0.68944849 | S15: =_xlfn.XLOOKUP(C15,Dados!$C$3:$C$329,Dados!$Q$3:$Q$329,"") -> 0.88967042 | T15: =_xlfn.XLOOKUP(C15,Dados!$C$3:$C$329,Dados!$R$3:$R$329,"") -> 0.93462577 | U15: =_xlfn.XLOOKUP(C15,Dados!$C$3:$C$329,Dados!$S$3:$S$329,"") -> 0.9590744 | V15: =_xlfn.XLOOKUP(C15,Dados!$C$3:$C$329,Dados!$T$3:$T$329,"") -> 1823.2505 | W15: =_xlfn.XLOOKUP(C15,Dados!$C$3:$C$329,Dados!$U$3:$U$329,"") -> 1645.3946 | X15: =_xlfn.XLOOKUP(C15,Dados!$C$3:$C$329,Dados!$V$3:$V$329,"") -> 1314.4106 | Y15: =_xlfn.XLOOKUP(C15,Dados!$C$3:$C$329,Dados!$W$3:$W$329,"") -> 1169.1542 | Z15: =_xlfn.XLOOKUP(C15,Dados!$C$3:$C$329,Dados!$X$3:$X$329,"") -> 1092.1156 | AF15: 0.011928232 | AG15: 0.010043134 | AH15: 0.046387794 | AI15: 0.049609441 | AJ15: #DIV/0! | AK15: {=_xlfn.XLOOKUP(C15,Dados!$C$3:$C$329,Dados!$Z$3:'Dados'!$Z$329,"")} -> 17.776631 | AL15: {=_xlfn.XLOOKUP(C15,Dados!$C$3:$C$329,Dados!$AA$3:'Dados'!$AA$329,"")} -> 19.124782 | AM15: {=_xlfn.XLOOKUP(C15,Dados!$C$3:$C$329,Dados!$AB$3:'Dados'!$AB$329,"")} -> 17.728638 | AN15: {=_xlfn.XLOOKUP(C15,Dados!$C$3:$C$329,Dados!$AC$3:'Dados'!$AC$329,"")} -> 13.856341 | AO15: {=_xlfn.XLOOKUP(C15,Dados!$C$3:$C$329,Dados!$AD$3:'Dados'!$AD$329,"")} -> 13.827436
A16: 73 | B16: Consórcio Público Intermunicipal de Saúde da Região de Jales - CONSIRJ | C16: 04.685.273/0001-78 | D16: São Paulo | E16: Sudeste | F16: =_xlfn.XLOOKUP(C16,Dados!$C$3:$C$329,Dados!$D$3:$D$329,"") -> 23 | G16: =_xlfn.XLOOKUP(C16,Dados!$C$3:$C$329,Dados!$E$3:$E$329,"") -> 156029 | H16: =_xlfn.XLOOKUP(C16,Dados!$C$3:$C$329,Dados!$F$3:$F$329,"") -> 156617 | I16: =_xlfn.XLOOKUP(C16,Dados!$C$3:$C$329,Dados!$G$3:$G$329,"") -> 157205 | J16: =_xlfn.XLOOKUP(C16,Dados!$C$3:$C$329,Dados!$H$3:$H$329,"") -> 157793 | K16: =_xlfn.XLOOKUP(C16,Dados!$C$3:$C$329,Dados!$I$3:$I$329,"") -> 157579 | L16: =_xlfn.XLOOKUP(C16,Dados!$C$3:$C$329,Dados!$J$3:$J$329,"") -> 16 | M16: =_xlfn.XLOOKUP(C16,Dados!$C$3:$C$329,Dados!$K$3:$K$329,"") -> Sudeste | N16: =_xlfn.XLOOKUP(C16,Dados!$C$3:$C$329,Dados!$L$3:$L$329,"") -> 3 | O16: =_xlfn.XLOOKUP(C16,Dados!$C$3:$C$329,Dados!$M$3:$M$329,"") -> 0.69895181 | P16: =_xlfn.XLOOKUP(C16,Dados!$C$3:$C$329,Dados!$N$3:$N$329,"") -> 0.65878188 | Q16: =_xlfn.XLOOKUP(C16,Dados!$C$3:$C$329,Dados!$O$3:$O$329,"") -> 0.64871904 | R16: =_xlfn.XLOOKUP(C16,Dados!$C$3:$C$329,Dados!$P$3:$P$329,"") -> 0.6285974 | S16: =_xlfn.XLOOKUP(C16,Dados!$C$3:$C$329,Dados!$Q$3:$Q$329,"") -> 0.66292271 | T16: =_xlfn.XLOOKUP(C16,Dados!$C$3:$C$329,Dados!$R$3:$R$329,"") -> 0.71904695 | U16: =_xlfn.XLOOKUP(C16,Dados!$C$3:$C$329,Dados!$S$3:$S$329,"") -> 0.93183842 | V16: =_xlfn.XLOOKUP(C16,Dados!$C$3:$C$329,Dados!$T$3:$T$329,"") -> 1659.3199 | W16: =_xlfn.XLOOKUP(C16,Dados!$C$3:$C$329,Dados!$U$3:$U$329,"") -> 1568.1934 | X16: =_xlfn.XLOOKUP(C16,Dados!$C$3:$C$329,Dados!$V$3:$V$329,"") -> 1384.1494 | Y16: =_xlfn.XLOOKUP(C16,Dados!$C$3:$C$329,Dados!$W$3:$W$329,"") -> 1079.5765 | Z16: =_xlfn.XLOOKUP(C16,Dados!$C$3:$C$329,Dados!$X$3:$X$329,"") -> 917.82557 | AF16: 0.46845504 | AG16: 0.4407927 | AH16: 0.38073139 | AI16: 0.38902849 | AJ16: 0.39819332 | AK16: {=_xlfn.XLOOKUP(C16,Dados!$C$3:$C$329,Dados!$Z$3:'Dados'!$Z$329,"")} -> 11.568676 | AL16: {=_xlfn.XLOOKUP(C16,Dados!$C$3:$C$329,Dados!$AA$3:'Dados'!$AA$329,"")} -> 7.7012713 | AM16: {=_xlfn.XLOOKUP(C16,Dados!$C$3:$C$329,Dados!$AB$3:'Dados'!$AB$329,"")} -> 6.703559 | AN16: {=_xlfn.XLOOKUP(C16,Dados!$C$3:$C$329,Dados!$AC$3:'Dados'!$AC$329,"")} -> 7.7847496 | AO16: {=_xlfn.XLOOKUP(C16,Dados!$C$3:$C$329,Dados!$AD$3:'Dados'!$AD$329,"")} -> 4.5688448
A17: 74 | B17: Consórcio Intermunicipal Serra da Mantiqueira - CISMA | C17: 04.894.776/0001-53 | D17: São Paulo | E17: Sudeste | F17: =_xlfn.XLOOKUP(C17,Dados!$C$3:$C$329,Dados!$D$3:$D$329,"") -> 23 | G17: =_xlfn.XLOOKUP(C17,Dados!$C$3:$C$329,Dados!$E$3:$E$329,"") -> 296540 | H17: =_xlfn.XLOOKUP(C17,Dados!$C$3:$C$329,Dados!$F$3:$F$329,"") -> 296131.67 | I17: =_xlfn.XLOOKUP(C17,Dados!$C$3:$C$329,Dados!$G$3:$G$329,"") -> 295723.33 | J17: =_xlfn.XLOOKUP(C17,Dados!$C$3:$C$329,Dados!$H$3:$H$329,"") -> 295315 | K17: =_xlfn.XLOOKUP(C17,Dados!$C$3:$C$329,Dados!$I$3:$I$329,"") -> 292667 | L17: =_xlfn.XLOOKUP(C17,Dados!$C$3:$C$329,Dados!$J$3:$J$329,"") -> 6 | M17: =_xlfn.XLOOKUP(C17,Dados!$C$3:$C$329,Dados!$K$3:$K$329,"") -> Sudeste | N17: =_xlfn.XLOOKUP(C17,Dados!$C$3:$C$329,Dados!$L$3:$L$329,"") -> 31 | O17: =_xlfn.XLOOKUP(C17,Dados!$C$3:$C$329,Dados!$M$3:$M$329,"") -> 0.74886154 | P17: =_xlfn.XLOOKUP(C17,Dados!$C$3:$C$329,Dados!$N$3:$N$329,"") -> 0.73403488 | Q17: =_xlfn.XLOOKUP(C17,Dados!$C$3:$C$329,Dados!$O$3:$O$329,"") -> 0.72180664 | R17: =_xlfn.XLOOKUP(C17,Dados!$C$3:$C$329,Dados!$P$3:$P$329,"") -> 0.70937415 | S17: =_xlfn.XLOOKUP(C17,Dados!$C$3:$C$329,Dados!$Q$3:$Q$329,"") -> 0.88930052 | T17: =_xlfn.XLOOKUP(C17,Dados!$C$3:$C$329,Dados!$R$3:$R$329,"") -> 0.92660761 | U17: =_xlfn.XLOOKUP(C17,Dados!$C$3:$C$329,Dados!$S$3:$S$329,"") -> 0.99328963 | V17: =_xlfn.XLOOKUP(C17,Dados!$C$3:$C$329,Dados!$T$3:$T$329,"") -> 1661.8817 | W17: =_xlfn.XLOOKUP(C17,Dados!$C$3:$C$329,Dados!$U$3:$U$329,"") -> 1461.9366 | X17: =_xlfn.XLOOKUP(C17,Dados!$C$3:$C$329,Dados!$V$3:$V$329,"") -> 1253.4625 | Y17: =_xlfn.XLOOKUP(C17,Dados!$C$3:$C$329,Dados!$W$3:$W$329,"") -> 1113.3872 | Z17: =_xlfn.XLOOKUP(C17,Dados!$C$3:$C$329,Dados!$X$3:$X$329,"") -> 1012.6498 | AF17: 0.13030366 | AG17: 0.22545791 | AH17: #DIV/0! | AI17: #DIV/0! | AJ17: #DIV/0! | AK17: {=_xlfn.XLOOKUP(C17,Dados!$C$3:$C$329,Dados!$Z$3:'Dados'!$Z$329,"")} -> 19.07196 | AL17: {=_xlfn.XLOOKUP(C17,Dados!$C$3:$C$329,Dados!$AA$3:'Dados'!$AA$329,"")} -> 15.755255 | AM17: {=_xlfn.XLOOKUP(C17,Dados!$C$3:$C$329,Dados!$AB$3:'Dados'!$AB$329,"")} -> 13.225023 | AN17: {=_xlfn.XLOOKUP(C17,Dados!$C$3:$C$329,Dados!$AC$3:'Dados'!$AC$329,"")} -> 10.870129 | AO17: {=_xlfn.XLOOKUP(C17,Dados!$C$3:$C$329,Dados!$AD$3:'Dados'!$AD$329,"")} -> 9.518709
A18: 75 | B18: Consórcio Intermunicipal do Vale do Paranapanema: Saúde - CIVAP SAÚDE | C18: 04.903.422/0001-28 | D18: São Paulo | E18: Sudeste | F18: =_xlfn.XLOOKUP(C18,Dados!$C$3:$C$329,Dados!$D$3:$D$329,"") -> 23 | G18: =_xlfn.XLOOKUP(C18,Dados!$C$3:$C$329,Dados!$E$3:$E$329,"") -> 240384 | H18: =_xlfn.XLOOKUP(C18,Dados!$C$3:$C$329,Dados!$F$3:$F$329,"") -> 243569 | I18: =_xlfn.XLOOKUP(C18,Dados!$C$3:$C$329,Dados!$G$3:$G$329,"") -> 246754 | J18: =_xlfn.XLOOKUP(C18,Dados!$C$3:$C$329,Dados!$H$3:$H$329,"") -> 249939 | K18: =_xlfn.XLOOKUP(C18,Dados!$C$3:$C$329,Dados!$I$3:$I$329,"") -> 248721 | L18: =_xlfn.XLOOKUP(C18,Dados!$C$3:$C$329,Dados!$J$3:$J$329,"") -> 12 | M18: =_xlfn.XLOOKUP(C18,Dados!$C$3:$C$329,Dados!$K$3:$K$329,"") -> Sudeste | N18: =_xlfn.XLOOKUP(C18,Dados!$C$3:$C$329,Dados!$L$3:$L$329,"") -> 3 | O18: =_xlfn.XLOOKUP(C18,Dados!$C$3:$C$329,Dados!$M$3:$M$329,"") -> 0.80308569 | P18: =_xlfn.XLOOKUP(C18,Dados!$C$3:$C$329,Dados!$N$3:$N$329,"") -> 0.77511902 | Q18: =_xlfn.XLOOKUP(C18,Dados!$C$3:$C$329,Dados!$O$3:$O$329,"") -> 0.76374664 | R18: =_xlfn.XLOOKUP(C18,Dados!$C$3:$C$329,Dados!$P$3:$P$329,"") -> 0.74834568 | S18: =_xlfn.XLOOKUP(C18,Dados!$C$3:$C$329,Dados!$Q$3:$Q$329,"") -> 0.94234574 | T18: =_xlfn.XLOOKUP(C18,Dados!$C$3:$C$329,Dados!$R$3:$R$329,"") -> 0.94395543 | U18: =_xlfn.XLOOKUP(C18,Dados!$C$3:$C$329,Dados!$S$3:$S$329,"") -> 0.97314885 | V18: =_xlfn.XLOOKUP(C18,Dados!$C$3:$C$329,Dados!$T$3:$T$329,"") -> 1879.0973 | W18: =_xlfn.XLOOKUP(C18,Dados!$C$3:$C$329,Dados!$U$3:$U$329,"") -> 1520.793 | X18: =_xlfn.XLOOKUP(C18,Dados!$C$3:$C$329,Dados!$V$3:$V$329,"") -> 1230.8447 | Y18: =_xlfn.XLOOKUP(C18,Dados!$C$3:$C$329,Dados!$W$3:$W$329,"") -> 1143.3285 | Z18: =_xlfn.XLOOKUP(C18,Dados!$C$3:$C$329,Dados!$X$3:$X$329,"") -> 1044.4846 | AF18: 0.2785387 | AG18: 0.2246609 | AH18: 0.13592819 | AI18: 0.44276695 | AJ18: 0.42327194 | AK18: {=_xlfn.XLOOKUP(C18,Dados!$C$3:$C$329,Dados!$Z$3:'Dados'!$Z$329,"")} -> 21.423606 | AL18: {=_xlfn.XLOOKUP(C18,Dados!$C$3:$C$329,Dados!$AA$3:'Dados'!$AA$329,"")} -> 19.616926 | AM18: {=_xlfn.XLOOKUP(C18,Dados!$C$3:$C$329,Dados!$AB$3:'Dados'!$AB$329,"")} -> 16.752458 | AN18: {=_xlfn.XLOOKUP(C18,Dados!$C$3:$C$329,Dados!$AC$3:'Dados'!$AC$329,"")} -> 13.5077 | AO18: {=_xlfn.XLOOKUP(C18,Dados!$C$3:$C$329,Dados!$AD$3:'Dados'!$AD$329,"")} -> 12.361316
A19: 76 | B19: Consórcio Intermunicipal de Saúde 8 de Abril - CON8 | C19: 08.996.378/0001-07 | D19: São Paulo | E19: Sudeste | F19: =_xlfn.XLOOKUP(C19,Dados!$C$3:$C$329,Dados!$D$3:$D$329,"") -> 17 | G19: =_xlfn.XLOOKUP(C19,Dados!$C$3:$C$329,Dados!$E$3:$E$329,"") -> 505119 | H19: =_xlfn.XLOOKUP(C19,Dados!$C$3:$C$329,Dados!$F$3:$F$329,"") -> 503634 | I19: =_xlfn.XLOOKUP(C19,Dados!$C$3:$C$329,Dados!$G$3:$G$329,"") -> 502149 | J19: =_xlfn.XLOOKUP(C19,Dados!$C$3:$C$329,Dados!$H$3:$H$329,"") -> 500664 | K19: =_xlfn.XLOOKUP(C19,Dados!$C$3:$C$329,Dados!$I$3:$I$329,"") -> 497103 | L19: =_xlfn.XLOOKUP(C19,Dados!$C$3:$C$329,Dados!$J$3:$J$329,"") -> 6 | M19: =_xlfn.XLOOKUP(C19,Dados!$C$3:$C$329,Dados!$K$3:$K$329,"") -> Sudeste | N19: =_xlfn.XLOOKUP(C19,Dados!$C$3:$C$329,Dados!$L$3:$L$329,"") -> 3 | O19: =_xlfn.XLOOKUP(C19,Dados!$C$3:$C$329,Dados!$M$3:$M$329,"") -> 0.81049006 | P19: =_xlfn.XLOOKUP(C19,Dados!$C$3:$C$329,Dados!$N$3:$N$329,"") -> 0.78832706 | Q19: =_xlfn.XLOOKUP(C19,Dados!$C$3:$C$329,Dados!$O$3:$O$329,"") -> 0.79673503 | R19: =_xlfn.XLOOKUP(C19,Dados!$C$3:$C$329,Dados!$P$3:$P$329,"") -> 0.78599364 | S19: =_xlfn.XLOOKUP(C19,Dados!$C$3:$C$329,Dados!$Q$3:$Q$329,"") -> 0.95112229 | T19: =_xlfn.XLOOKUP(C19,Dados!$C$3:$C$329,Dados!$R$3:$R$329,"") -> 0.95568937 | U19: =_xlfn.XLOOKUP(C19,Dados!$C$3:$C$329,Dados!$S$3:$S$329,"") -> 0.99050318 | V19: =_xlfn.XLOOKUP(C19,Dados!$C$3:$C$329,Dados!$T$3:$T$329,"") -> 1712.7379 | W19: =_xlfn.XLOOKUP(C19,Dados!$C$3:$C$329,Dados!$U$3:$U$329,"") -> 1323.7658 | X19: =_xlfn.XLOOKUP(C19,Dados!$C$3:$C$329,Dados!$V$3:$V$329,"") -> 1141.1374 | Y19: =_xlfn.XLOOKUP(C19,Dados!$C$3:$C$329,Dados!$W$3:$W$329,"") -> 1121.438 | Z19: =_xlfn.XLOOKUP(C19,Dados!$C$3:$C$329,Dados!$X$3:$X$329,"") -> 1057.996 | AF19: 0.29871023 | AG19: 0.28878372 | AH19: 0.43663624 | AI19: 0.54254773 | AJ19: 0.56640988 | AK19: {=_xlfn.XLOOKUP(C19,Dados!$C$3:$C$329,Dados!$Z$3:'Dados'!$Z$329,"")} -> 14.29952 | AL19: {=_xlfn.XLOOKUP(C19,Dados!$C$3:$C$329,Dados!$AA$3:'Dados'!$AA$329,"")} -> 13.867561 | AM19: {=_xlfn.XLOOKUP(C19,Dados!$C$3:$C$329,Dados!$AB$3:'Dados'!$AB$329,"")} -> 13.631325 | AN19: {=_xlfn.XLOOKUP(C19,Dados!$C$3:$C$329,Dados!$AC$3:'Dados'!$AC$329,"")} -> 11.292925 | AO19: {=_xlfn.XLOOKUP(C19,Dados!$C$3:$C$329,Dados!$AD$3:'Dados'!$AD$329,"")} -> 9.90266
A20: 79 | B20: Consórcio Intermunicipal da Região Oeste Metropolitana de São Paulo - CIOESTE | C20: 20.301.484/0001-16 | D20: São Paulo | E20: Sudeste | F20: =_xlfn.XLOOKUP(C20,Dados!$C$3:$C$329,Dados!$D$3:$D$329,"") -> 11 | G20: =_xlfn.XLOOKUP(C20,Dados!$C$3:$C$329,Dados!$E$3:$E$329,"") -> 2570822 | H20: =_xlfn.XLOOKUP(C20,Dados!$C$3:$C$329,Dados!$F$3:$F$329,"") -> 2524064 | I20: =_xlfn.XLOOKUP(C20,Dados!$C$3:$C$329,Dados!$G$3:$G$329,"") -> 2477306 | J20: =_xlfn.XLOOKUP(C20,Dados!$C$3:$C$329,Dados!$H$3:$H$329,"") -> 2430548 | K20: =_xlfn.XLOOKUP(C20,Dados!$C$3:$C$329,Dados!$I$3:$I$329,"") -> 2408835 | L20: =_xlfn.XLOOKUP(C20,Dados!$C$3:$C$329,Dados!$J$3:$J$329,"") -> 12 | M20: =_xlfn.XLOOKUP(C20,Dados!$C$3:$C$329,Dados!$K$3:$K$329,"") -> Sudeste | N20: =_xlfn.XLOOKUP(C20,Dados!$C$3:$C$329,Dados!$L$3:$L$329,"") -> 41 | O20: =_xlfn.XLOOKUP(C20,Dados!$C$3:$C$329,Dados!$M$3:$M$329,"") -> 0.75646137 | P20: =_xlfn.XLOOKUP(C20,Dados!$C$3:$C$329,Dados!$N$3:$N$329,"") -> 0.7312482 | Q20: =_xlfn.XLOOKUP(C20,Dados!$C$3:$C$329,Dados!$O$3:$O$329,"") -> 0.72324392 | R20: =_xlfn.XLOOKUP(C20,Dados!$C$3:$C$329,Dados!$P$3:$P$329,"") -> 0.70842937 | S20: =_xlfn.XLOOKUP(C20,Dados!$C$3:$C$329,Dados!$Q$3:$Q$329,"") -> 0.84670888 | T20: =_xlfn.XLOOKUP(C20,Dados!$C$3:$C$329,Dados!$R$3:$R$329,"") -> 0.9697355 | U20: =_xlfn.XLOOKUP(C20,Dados!$C$3:$C$329,Dados!$S$3:$S$329,"") -> 0.99558749 | V20: =_xlfn.XLOOKUP(C20,Dados!$C$3:$C$329,Dados!$T$3:$T$329,"") -> 1729.2127 | W20: =_xlfn.XLOOKUP(C20,Dados!$C$3:$C$329,Dados!$U$3:$U$329,"") -> 1600.1374 | X20: =_xlfn.XLOOKUP(C20,Dados!$C$3:$C$329,Dados!$V$3:$V$329,"") -> 1544.5148 | Y20: =_xlfn.XLOOKUP(C20,Dados!$C$3:$C$329,Dados!$W$3:$W$329,"") -> 1373.2211 | Z20: =_xlfn.XLOOKUP(C20,Dados!$C$3:$C$329,Dados!$X$3:$X$329,"") -> 1193.8922 | AF20: 0.16084912 | AG20: 0.067809195 | AH20: 0.10928637 | AI20: 0.16831434 | AJ20: #DIV/0! | AK20: {=_xlfn.XLOOKUP(C20,Dados!$C$3:$C$329,Dados!$Z$3:'Dados'!$Z$329,"")} -> 19.985791 | AL20: {=_xlfn.XLOOKUP(C20,Dados!$C$3:$C$329,Dados!$AA$3:'Dados'!$AA$329,"")} -> 18.35499 | AM20: {=_xlfn.XLOOKUP(C20,Dados!$C$3:$C$329,Dados!$AB$3:'Dados'!$AB$329,"")} -> 15.843111 | AN20: {=_xlfn.XLOOKUP(C20,Dados!$C$3:$C$329,Dados!$AC$3:'Dados'!$AC$329,"")} -> 14.292029 | AO20: {=_xlfn.XLOOKUP(C20,Dados!$C$3:$C$329,Dados!$AD$3:'Dados'!$AD$329,"")} -> 12.22522
A21: 81 | B21: Consórcio Público Intermunicipal de Saúde da Região de Catanduva - CONSIRC | C21: 25.103.884/0001-30 | D21: São Paulo | E21: Sudeste | F21: =_xlfn.XLOOKUP(C21,Dados!$C$3:$C$329,Dados!$D$3:$D$329,"") -> 8 | G21: =_xlfn.XLOOKUP(C21,Dados!$C$3:$C$329,Dados!$E$3:$E$329,"") -> 335730 | H21: =_xlfn.XLOOKUP(C21,Dados!$C$3:$C$329,Dados!$F$3:$F$329,"") -> 343428.67 | I21: =_xlfn.XLOOKUP(C21,Dados!$C$3:$C$329,Dados!$G$3:$G$329,"") -> 351127.33 | J21: =_xlfn.XLOOKUP(C21,Dados!$C$3:$C$329,Dados!$H$3:$H$329,"") -> 358826 | K21: =_xlfn.XLOOKUP(C21,Dados!$C$3:$C$329,Dados!$I$3:$I$329,"") -> 356301 | L21: =_xlfn.XLOOKUP(C21,Dados!$C$3:$C$329,Dados!$J$3:$J$329,"") -> 22 | M21: =_xlfn.XLOOKUP(C21,Dados!$C$3:$C$329,Dados!$K$3:$K$329,"") -> Sudeste | N21: =_xlfn.XLOOKUP(C21,Dados!$C$3:$C$329,Dados!$L$3:$L$329,"") -> 4 | O21: =_xlfn.XLOOKUP(C21,Dados!$C$3:$C$329,Dados!$M$3:$M$329,"") -> 0.74847003 | P21: =_xlfn.XLOOKUP(C21,Dados!$C$3:$C$329,Dados!$N$3:$N$329,"") -> 0.71332644 | Q21: =_xlfn.XLOOKUP(C21,Dados!$C$3:$C$329,Dados!$O$3:$O$329,"") -> 0.69010145 | R21: =_xlfn.XLOOKUP(C21,Dados!$C$3:$C$329,Dados!$P$3:$P$329,"") -> 0.68864352 | S21: =_xlfn.XLOOKUP(C21,Dados!$C$3:$C$329,Dados!$Q$3:$Q$329,"") -> 0.84137302 | T21: =_xlfn.XLOOKUP(C21,Dados!$C$3:$C$329,Dados!$R$3:$R$329,"") -> 0.94129609 | U21: =_xlfn.XLOOKUP(C21,Dados!$C$3:$C$329,Dados!$S$3:$S$329,"") -> 0.9145085 | V21: =_xlfn.XLOOKUP(C21,Dados!$C$3:$C$329,Dados!$T$3:$T$329,"") -> 1750.7373 | W21: =_xlfn.XLOOKUP(C21,Dados!$C$3:$C$329,Dados!$U$3:$U$329,"") -> 1430.3927 | X21: =_xlfn.XLOOKUP(C21,Dados!$C$3:$C$329,Dados!$V$3:$V$329,"") -> 1199.3046 | Y21: =_xlfn.XLOOKUP(C21,Dados!$C$3:$C$329,Dados!$W$3:$W$329,"") -> 1015.3191 | Z21: =_xlfn.XLOOKUP(C21,Dados!$C$3:$C$329,Dados!$X$3:$X$329,"") -> 952.51553 | AF21: 0.12264524 | AG21: 0.10589656 | AH21: 0.15680471 | AI21: 0.19952938 | AJ21: 0.30633504 | AK21: {=_xlfn.XLOOKUP(C21,Dados!$C$3:$C$329,Dados!$Z$3:'Dados'!$Z$329,"")} -> 14.641018 | AL21: {=_xlfn.XLOOKUP(C21,Dados!$C$3:$C$329,Dados!$AA$3:'Dados'!$AA$329,"")} -> 14.940925 | AM21: {=_xlfn.XLOOKUP(C21,Dados!$C$3:$C$329,Dados!$AB$3:'Dados'!$AB$329,"")} -> 15.212345 | AN21: {=_xlfn.XLOOKUP(C21,Dados!$C$3:$C$329,Dados!$AC$3:'Dados'!$AC$329,"")} -> 10.0723 | AO21: {=_xlfn.XLOOKUP(C21,Dados!$C$3:$C$329,Dados!$AD$3:'Dados'!$AD$329,"")} -> 7.7865962
A22: 82 | B22: Consórcio Intermunicipal do Centro do Estado de Sao Paulo - Cicesp - CICESP | C22: 36.580.300/0001-34 | D22: São Paulo | E22: Sudeste | F22: =_xlfn.XLOOKUP(C22,Dados!$C$3:$C$329,Dados!$D$3:$D$329,"") -> 6 | G22: =_xlfn.XLOOKUP(C22,Dados!$C$3:$C$329,Dados!$E$3:$E$329,"") -> 208035 | H22: =_xlfn.XLOOKUP(C22,Dados!$C$3:$C$329,Dados!$F$3:$F$329,"") -> 212304 | I22: =_xlfn.XLOOKUP(C22,Dados!$C$3:$C$329,Dados!$G$3:$G$329,"") -> 216573 | J22: =_xlfn.XLOOKUP(C22,Dados!$C$3:$C$329,Dados!$H$3:$H$329,"") -> 220842 | K22: =_xlfn.XLOOKUP(C22,Dados!$C$3:$C$329,Dados!$I$3:$I$329,"") -> 219130 | L22: =_xlfn.XLOOKUP(C22,Dados!$C$3:$C$329,Dados!$J$3:$J$329,"") -> 8 | M22: =_xlfn.XLOOKUP(C22,Dados!$C$3:$C$329,Dados!$K$3:$K$329,"") -> Sudeste | N22: =_xlfn.XLOOKUP(C22,Dados!$C$3:$C$329,Dados!$L$3:$L$329,"") -> 26 | O22: =_xlfn.XLOOKUP(C22,Dados!$C$3:$C$329,Dados!$M$3:$M$329,"") -> 0.66661912 | P22: =_xlfn.XLOOKUP(C22,Dados!$C$3:$C$329,Dados!$N$3:$N$329,"") -> 0.64949177 | Q22: =_xlfn.XLOOKUP(C22,Dados!$C$3:$C$329,Dados!$O$3:$O$329,"") -> 0.61243139 | R22: =_xlfn.XLOOKUP(C22,Dados!$C$3:$C$329,Dados!$P$3:$P$329,"") -> 0.60743065 | S22: =_xlfn.XLOOKUP(C22,Dados!$C$3:$C$329,Dados!$Q$3:$Q$329,"") -> 0.68374088 | T22: =_xlfn.XLOOKUP(C22,Dados!$C$3:$C$329,Dados!$R$3:$R$329,"") -> 0.87678168 | U22: =_xlfn.XLOOKUP(C22,Dados!$C$3:$C$329,Dados!$S$3:$S$329,"") -> 0.84644449 | V22: =_xlfn.XLOOKUP(C22,Dados!$C$3:$C$329,Dados!$T$3:$T$329,"") -> 1638.2104 | W22: =_xlfn.XLOOKUP(C22,Dados!$C$3:$C$329,Dados!$U$3:$U$329,"") -> 1369.3973 | X22: =_xlfn.XLOOKUP(C22,Dados!$C$3:$C$329,Dados!$V$3:$V$329,"") -> 1174.7981 | Y22: =_xlfn.XLOOKUP(C22,Dados!$C$3:$C$329,Dados!$W$3:$W$329,"") -> 1011.8936 | Z22: =_xlfn.XLOOKUP(C22,Dados!$C$3:$C$329,Dados!$X$3:$X$329,"") -> 904.32633 | AF22: 0.38359516 | AG22: 0.047598282 | AH22: 0.14661501 | AI22: 0.58456 | AJ22: #DIV/0! | AK22: {=_xlfn.XLOOKUP(C22,Dados!$C$3:$C$329,Dados!$Z$3:'Dados'!$Z$329,"")} -> 10.047872 | AL22: {=_xlfn.XLOOKUP(C22,Dados!$C$3:$C$329,Dados!$AA$3:'Dados'!$AA$329,"")} -> 10.132711 | AM22: {=_xlfn.XLOOKUP(C22,Dados!$C$3:$C$329,Dados!$AB$3:'Dados'!$AB$329,"")} -> 8.963652 | AN22: {=_xlfn.XLOOKUP(C22,Dados!$C$3:$C$329,Dados!$AC$3:'Dados'!$AC$329,"")} -> 6.8455593 | AO22: {=_xlfn.XLOOKUP(C22,Dados!$C$3:$C$329,Dados!$AD$3:'Dados'!$AD$329,"")} -> 6.3101675
A23: 119 | B23: Consórcio Público da Região Noroeste - CIM NOROESTE | C23: 02.236.721/0001-20 | D23: Espírito Santo | E23: Sudeste | F23: =_xlfn.XLOOKUP(C23,Dados!$C$3:$C$329,Dados!$D$3:$D$329,"") -> 31 | G23: =_xlfn.XLOOKUP(C23,Dados!$C$3:$C$329,Dados!$E$3:$E$329,"") -> 410727 | H23: =_xlfn.XLOOKUP(C23,Dados!$C$3:$C$329,Dados!$F$3:$F$329,"") -> 412471.67 | I23: =_xlfn.XLOOKUP(C23,Dados!$C$3:$C$329,Dados!$G$3:$G$329,"") -> 414216.33 | J23: =_xlfn.XLOOKUP(C23,Dados!$C$3:$C$329,Dados!$H$3:$H$329,"") -> 415961 | K23: =_xlfn.XLOOKUP(C23,Dados!$C$3:$C$329,Dados!$I$3:$I$329,"") -> 413585 | L23: =_xlfn.XLOOKUP(C23,Dados!$C$3:$C$329,Dados!$J$3:$J$329,"") -> 16 | M23: =_xlfn.XLOOKUP(C23,Dados!$C$3:$C$329,Dados!$K$3:$K$329,"") -> Sudeste | N23: =_xlfn.XLOOKUP(C23,Dados!$C$3:$C$329,Dados!$L$3:$L$329,"") -> 17 | O23: =_xlfn.XLOOKUP(C23,Dados!$C$3:$C$329,Dados!$M$3:$M$329,"") -> 0.70896922 | P23: =_xlfn.XLOOKUP(C23,Dados!$C$3:$C$329,Dados!$N$3:$N$329,"") -> 0.68053108 | Q23: =_xlfn.XLOOKUP(C23,Dados!$C$3:$C$329,Dados!$O$3:$O$329,"") -> 0.6517438 | R23: =_xlfn.XLOOKUP(C23,Dados!$C$3:$C$329,Dados!$P$3:$P$329,"") -> 0.63899642 | S23: =_xlfn.XLOOKUP(C23,Dados!$C$3:$C$329,Dados!$Q$3:$Q$329,"") -> 0.6683626 | T23: =_xlfn.XLOOKUP(C23,Dados!$C$3:$C$329,Dados!$R$3:$R$329,"") -> 0.71483375 | U23: =_xlfn.XLOOKUP(C23,Dados!$C$3:$C$329,Dados!$S$3:$S$329,"") -> 0.80492028 | V23: =_xlfn.XLOOKUP(C23,Dados!$C$3:$C$329,Dados!$T$3:$T$329,"") -> 1764.4255 | W23: =_xlfn.XLOOKUP(C23,Dados!$C$3:$C$329,Dados!$U$3:$U$329,"") -> 1448.3255 | X23: =_xlfn.XLOOKUP(C23,Dados!$C$3:$C$329,Dados!$V$3:$V$329,"") -> 1145.6989 | Y23: =_xlfn.XLOOKUP(C23,Dados!$C$3:$C$329,Dados!$W$3:$W$329,"") -> 925.4742 | Z23: =_xlfn.XLOOKUP(C23,Dados!$C$3:$C$329,Dados!$X$3:$X$329,"") -> 855.35997 | AF23: #DIV/0! | AG23: #DIV/0! | AH23: #DIV/0! | AI23: #DIV/0! | AJ23: #DIV/0! | AK23: {=_xlfn.XLOOKUP(C23,Dados!$C$3:$C$329,Dados!$Z$3:'Dados'!$Z$329,"")} -> 12.834087 | AL23: {=_xlfn.XLOOKUP(C23,Dados!$C$3:$C$329,Dados!$AA$3:'Dados'!$AA$329,"")} -> 11.139861 | AM23: {=_xlfn.XLOOKUP(C23,Dados!$C$3:$C$329,Dados!$AB$3:'Dados'!$AB$329,"")} -> 10.137703 | AN23: {=_xlfn.XLOOKUP(C23,Dados!$C$3:$C$329,Dados!$AC$3:'Dados'!$AC$329,"")} -> 7.9000676 | AO23: {=_xlfn.XLOOKUP(C23,Dados!$C$3:$C$329,Dados!$AD$3:'Dados'!$AD$329,"")} -> 7.1104199
A24: 120 | B24: Consórcio Público da Região Sudoeste Serrana - CIM PEDRA AZUL | C24: 02.760.004/0001-01 | D24: Espírito Santo | E24: Sudeste | F24: =_xlfn.XLOOKUP(C24,Dados!$C$3:$C$329,Dados!$D$3:$D$329,"") -> 26 | G24: =_xlfn.XLOOKUP(C24,Dados!$C$3:$C$329,Dados!$E$3:$E$329,"") -> 440989 | H24: =_xlfn.XLOOKUP(C24,Dados!$C$3:$C$329,Dados!$F$3:$F$329,"") -> 435525.33 | I24: =_xlfn.XLOOKUP(C24,Dados!$C$3:$C$329,Dados!$G$3:$G$329,"") -> 430061.67 | J24: =_xlfn.XLOOKUP(C24,Dados!$C$3:$C$329,Dados!$H$3:$H$329,"") -> 424598 | K24: =_xlfn.XLOOKUP(C24,Dados!$C$3:$C$329,Dados!$I$3:$I$329,"") -> 421471 | L24: =_xlfn.XLOOKUP(C24,Dados!$C$3:$C$329,Dados!$J$3:$J$329,"") -> 17 | M24: =_xlfn.XLOOKUP(C24,Dados!$C$3:$C$329,Dados!$K$3:$K$329,"") -> Sudeste | N24: =_xlfn.XLOOKUP(C24,Dados!$C$3:$C$329,Dados!$L$3:$L$329,"") -> 1 | O24: =_xlfn.XLOOKUP(C24,Dados!$C$3:$C$329,Dados!$M$3:$M$329,"") -> 0.65127469 | P24: =_xlfn.XLOOKUP(C24,Dados!$C$3:$C$329,Dados!$N$3:$N$329,"") -> 0.63130987 | Q24: =_xlfn.XLOOKUP(C24,Dados!$C$3:$C$329,Dados!$O$3:$O$329,"") -> 0.59044635 | R24: =_xlfn.XLOOKUP(C24,Dados!$C$3:$C$329,Dados!$P$3:$P$329,"") -> 0.57281799 | S24: =_xlfn.XLOOKUP(C24,Dados!$C$3:$C$329,Dados!$Q$3:$Q$329,"") -> 0.39767495 | T24: =_xlfn.XLOOKUP(C24,Dados!$C$3:$C$329,Dados!$R$3:$R$329,"") -> 0.46251154 | U24: =_xlfn.XLOOKUP(C24,Dados!$C$3:$C$329,Dados!$S$3:$S$329,"") -> 0.76356485 | V24: =_xlfn.XLOOKUP(C24,Dados!$C$3:$C$329,Dados!$T$3:$T$329,"") -> 1361.2708 | W24: =_xlfn.XLOOKUP(C24,Dados!$C$3:$C$329,Dados!$U$3:$U$329,"") -> 1223.2735 | X24: =_xlfn.XLOOKUP(C24,Dados!$C$3:$C$329,Dados!$V$3:$V$329,"") -> 1046.9626 | Y24: =_xlfn.XLOOKUP(C24,Dados!$C$3:$C$329,Dados!$W$3:$W$329,"") -> 829.24579 | Z24: =_xlfn.XLOOKUP(C24,Dados!$C$3:$C$329,Dados!$X$3:$X$329,"") -> 785.58886 | AF24: #DIV/0! | AG24: #DIV/0! | AH24: 0.0063913045 | AI24: 0.0079685424 | AJ24: 0.0088607439 | AK24: {=_xlfn.XLOOKUP(C24,Dados!$C$3:$C$329,Dados!$Z$3:'Dados'!$Z$329,"")} -> 11.019583 | AL24: {=_xlfn.XLOOKUP(C24,Dados!$C$3:$C$329,Dados!$AA$3:'Dados'!$AA$329,"")} -> 9.7618753 | AM24: {=_xlfn.XLOOKUP(C24,Dados!$C$3:$C$329,Dados!$AB$3:'Dados'!$AB$329,"")} -> 8.5344784 | AN24: {=_xlfn.XLOOKUP(C24,Dados!$C$3:$C$329,Dados!$AC$3:'Dados'!$AC$329,"")} -> 6.3434684 | AO24: {=_xlfn.XLOOKUP(C24,Dados!$C$3:$C$329,Dados!$AD$3:'Dados'!$AD$329,"")} -> 5.8157904
A25: 121 | B25: Consórcio Público da Região Expandida Sul - CIM EXPANDIDA SUL | C25: 03.657.784/0001-13 | D25: Espírito Santo | E25: Sudeste | F25: =_xlfn.XLOOKUP(C25,Dados!$C$3:$C$329,Dados!$D$3:$D$329,"") -> 19 | G25: =_xlfn.XLOOKUP(C25,Dados!$C$3:$C$329,Dados!$E$3:$E$329,"") -> 318635 | H25: =_xlfn.XLOOKUP(C25,Dados!$C$3:$C$329,Dados!$F$3:$F$329,"") -> 311015.33 | I25: =_xlfn.XLOOKUP(C25,Dados!$C$3:$C$329,Dados!$G$3:$G$329,"") -> 303395.67 | J25: =_xlfn.XLOOKUP(C25,Dados!$C$3:$C$329,Dados!$H$3:$H$329,"") -> 295776 | K25: =_xlfn.XLOOKUP(C25,Dados!$C$3:$C$329,Dados!$I$3:$I$329,"") -> 292307 | L25: =_xlfn.XLOOKUP(C25,Dados!$C$3:$C$329,Dados!$J$3:$J$329,"") -> 8 | M25: =_xlfn.XLOOKUP(C25,Dados!$C$3:$C$329,Dados!$K$3:$K$329,"") -> Sudeste | N25: =_xlfn.XLOOKUP(C25,Dados!$C$3:$C$329,Dados!$L$3:$L$329,"") -> 6 | O25: =_xlfn.XLOOKUP(C25,Dados!$C$3:$C$329,Dados!$M$3:$M$329,"") -> 0.68107196 | P25: =_xlfn.XLOOKUP(C25,Dados!$C$3:$C$329,Dados!$N$3:$N$329,"") -> 0.6484555 | Q25: =_xlfn.XLOOKUP(C25,Dados!$C$3:$C$329,Dados!$O$3:$O$329,"") -> 0.6195624 | R25: =_xlfn.XLOOKUP(C25,Dados!$C$3:$C$329,Dados!$P$3:$P$329,"") -> 0.60405543 | S25: =_xlfn.XLOOKUP(C25,Dados!$C$3:$C$329,Dados!$Q$3:$Q$329,"") -> 0.53901149 | T25: =_xlfn.XLOOKUP(C25,Dados!$C$3:$C$329,Dados!$R$3:$R$329,"") -> 0.83756125 | U25: =_xlfn.XLOOKUP(C25,Dados!$C$3:$C$329,Dados!$S$3:$S$329,"") -> 0.97265669 | V25: =_xlfn.XLOOKUP(C25,Dados!$C$3:$C$329,Dados!$T$3:$T$329,"") -> 1557.0239 | W25: =_xlfn.XLOOKUP(C25,Dados!$C$3:$C$329,Dados!$U$3:$U$329,"") -> 1409.1878 | X25: =_xlfn.XLOOKUP(C25,Dados!$C$3:$C$329,Dados!$V$3:$V$329,"") -> 1256.47 | Y25: =_xlfn.XLOOKUP(C25,Dados!$C$3:$C$329,Dados!$W$3:$W$329,"") -> 1043.2535 | Z25: =_xlfn.XLOOKUP(C25,Dados!$C$3:$C$329,Dados!$X$3:$X$329,"") -> 1119.4589 | AF25: 0.014442332 | AG25: 0.011965045 | AH25: #DIV/0! | AI25: #DIV/0! | AJ25: #DIV/0! | AK25: {=_xlfn.XLOOKUP(C25,Dados!$C$3:$C$329,Dados!$Z$3:'Dados'!$Z$329,"")} -> 10.549146 | AL25: {=_xlfn.XLOOKUP(C25,Dados!$C$3:$C$329,Dados!$AA$3:'Dados'!$AA$329,"")} -> 10.183987 | AM25: {=_xlfn.XLOOKUP(C25,Dados!$C$3:$C$329,Dados!$AB$3:'Dados'!$AB$329,"")} -> 6.1834008 | AN25: {=_xlfn.XLOOKUP(C25,Dados!$C$3:$C$329,Dados!$AC$3:'Dados'!$AC$329,"")} -> 4.4723642 | AO25: {=_xlfn.XLOOKUP(C25,Dados!$C$3:$C$329,Dados!$AD$3:'Dados'!$AD$329,"")} -> 3.373703
A26: 152 | B26: Consórcio Intermunicipal de Saúde da Região do Vale do Itapecerica - CISVI | C26: 00.639.952/0001-50 | D26: Minas Gerais | E26: Sudeste | F26: =_xlfn.XLOOKUP(C26,Dados!$C$3:$C$329,Dados!$D$3:$D$329,"") -> 29 | G26: =_xlfn.XLOOKUP(C26,Dados!$C$3:$C$329,Dados!$E$3:$E$329,"") -> 368774 | H26: =_xlfn.XLOOKUP(C26,Dados!$C$3:$C$329,Dados!$F$3:$F$329,"") -> 366492.33 | I26: =_xlfn.XLOOKUP(C26,Dados!$C$3:$C$329,Dados!$G$3:$G$329,"") -> 364210.67 | J26: =_xlfn.XLOOKUP(C26,Dados!$C$3:$C$329,Dados!$H$3:$H$329,"") -> 361929 | K26: =_xlfn.XLOOKUP(C26,Dados!$C$3:$C$329,Dados!$I$3:$I$329,"") -> 358827 | L26: =_xlfn.XLOOKUP(C26,Dados!$C$3:$C$329,Dados!$J$3:$J$329,"") -> 10 | M26: =_xlfn.XLOOKUP(C26,Dados!$C$3:$C$329,Dados!$K$3:$K$329,"") -> Sudeste | N26: =_xlfn.XLOOKUP(C26,Dados!$C$3:$C$329,Dados!$L$3:$L$329,"") -> 1 | O26: =_xlfn.XLOOKUP(C26,Dados!$C$3:$C$329,Dados!$M$3:$M$329,"") -> 0.77885758 | P26: =_xlfn.XLOOKUP(C26,Dados!$C$3:$C$329,Dados!$N$3:$N$329,"") -> 0.76983162 | Q26: =_xlfn.XLOOKUP(C26,Dados!$C$3:$C$329,Dados!$O$3:$O$329,"") -> 0.73416605 | R26: =_xlfn.XLOOKUP(C26,Dados!$C$3:$C$329,Dados!$P$3:$P$329,"") -> 0.71164231 | S26: =_xlfn.XLOOKUP(C26,Dados!$C$3:$C$329,Dados!$Q$3:$Q$329,"") -> 0.84992467 | T26: =_xlfn.XLOOKUP(C26,Dados!$C$3:$C$329,Dados!$R$3:$R$329,"") -> 0.91913871 | U26: =_xlfn.XLOOKUP(C26,Dados!$C$3:$C$329,Dados!$S$3:$S$329,"") -> 0.96979795 | V26: =_xlfn.XLOOKUP(C26,Dados!$C$3:$C$329,Dados!$T$3:$T$329,"") -> 1941.4016 | W26: =_xlfn.XLOOKUP(C26,Dados!$C$3:$C$329,Dados!$U$3:$U$329,"") -> 1591.6831 | X26: =_xlfn.XLOOKUP(C26,Dados!$C$3:$C$329,Dados!$V$3:$V$329,"") -> 1376.6618 | Y26: =_xlfn.XLOOKUP(C26,Dados!$C$3:$C$329,Dados!$W$3:$W$329,"") -> 1144.7789 | Z26: =_xlfn.XLOOKUP(C26,Dados!$C$3:$C$329,Dados!$X$3:$X$329,"") -> 1036.1581 | AF26: 0.11093601 | AG26: 0.27486223 | AH26: 0.27357339 | AI26: 0.28884176 | AJ26: 0 | AK26: {=_xlfn.XLOOKUP(C26,Dados!$C$3:$C$329,Dados!$Z$3:'Dados'!$Z$329,"")} -> 11.246606 | AL26: {=_xlfn.XLOOKUP(C26,Dados!$C$3:$C$329,Dados!$AA$3:'Dados'!$AA$329,"")} -> 9.2002061 | AM26: {=_xlfn.XLOOKUP(C26,Dados!$C$3:$C$329,Dados!$AB$3:'Dados'!$AB$329,"")} -> 9.4035027 | AN26: {=_xlfn.XLOOKUP(C26,Dados!$C$3:$C$329,Dados!$AC$3:'Dados'!$AC$329,"")} -> 8.7458673 | AO26: {=_xlfn.XLOOKUP(C26,Dados!$C$3:$C$329,Dados!$AD$3:'Dados'!$AD$329,"")} -> 5.7198093
A27: 157 | B27: Consórcio Intermunicipal de Saúde do Alto Jequitinhonha - CISAJE | C27: 00.699.767/0001-50 | D27: Minas Gerais | E27: Sudeste | F27: =_xlfn.XLOOKUP(C27,Dados!$C$3:$C$329,Dados!$D$3:$D$329,"") -> 29 | G27: =_xlfn.XLOOKUP(C27,Dados!$C$3:$C$329,Dados!$E$3:$E$329,"") -> 270752 | H27: =_xlfn.XLOOKUP(C27,Dados!$C$3:$C$329,Dados!$F$3:$F$329,"") -> 274237 | I27: =_xlfn.XLOOKUP(C27,Dados!$C$3:$C$329,Dados!$G$3:$G$329,"") -> 277722 | J27: =_xlfn.XLOOKUP(C27,Dados!$C$3:$C$329,Dados!$H$3:$H$329,"") -> 281207 | K27: =_xlfn.XLOOKUP(C27,Dados!$C$3:$C$329,Dados!$I$3:$I$329,"") -> 280685 | L27: =_xlfn.XLOOKUP(C27,Dados!$C$3:$C$329,Dados!$J$3:$J$329,"") -> 23 | M27: =_xlfn.XLOOKUP(C27,Dados!$C$3:$C$329,Dados!$K$3:$K$329,"") -> Sudeste | N27: =_xlfn.XLOOKUP(C27,Dados!$C$3:$C$329,Dados!$L$3:$L$329,"") -> 2 | O27: =_xlfn.XLOOKUP(C27,Dados!$C$3:$C$329,Dados!$M$3:$M$329,"") -> 0.6444107 | P27: =_xlfn.XLOOKUP(C27,Dados!$C$3:$C$329,Dados!$N$3:$N$329,"") -> 0.62870496 | Q27: =_xlfn.XLOOKUP(C27,Dados!$C$3:$C$329,Dados!$O$3:$O$329,"") -> 0.58040711 | R27: =_xlfn.XLOOKUP(C27,Dados!$C$3:$C$329,Dados!$P$3:$P$329,"") -> 0.57950652 | S27: =_xlfn.XLOOKUP(C27,Dados!$C$3:$C$329,Dados!$Q$3:$Q$329,"") -> 0.61011468 | T27: =_xlfn.XLOOKUP(C27,Dados!$C$3:$C$329,Dados!$R$3:$R$329,"") -> 0.7476919 | U27: =_xlfn.XLOOKUP(C27,Dados!$C$3:$C$329,Dados!$S$3:$S$329,"") -> 0.74920539 | V27: =_xlfn.XLOOKUP(C27,Dados!$C$3:$C$329,Dados!$T$3:$T$329,"") -> 2319.5202 | W27: =_xlfn.XLOOKUP(C27,Dados!$C$3:$C$329,Dados!$U$3:$U$329,"") -> 1906.9829 | X27: =_xlfn.XLOOKUP(C27,Dados!$C$3:$C$329,Dados!$V$3:$V$329,"") -> 1490.8746 | Y27: =_xlfn.XLOOKUP(C27,Dados!$C$3:$C$329,Dados!$W$3:$W$329,"") -> 1215.9936 | Z27: =_xlfn.XLOOKUP(C27,Dados!$C$3:$C$329,Dados!$X$3:$X$329,"") -> 1094.8683 | AF27: 0.2034998 | AG27: 0.17868442 | AH27: 0.23588136 | AI27: 0.30377561 | AJ27: #DIV/0! | AK27: {=_xlfn.XLOOKUP(C27,Dados!$C$3:$C$329,Dados!$Z$3:'Dados'!$Z$329,"")} -> 14.696035 | AL27: {=_xlfn.XLOOKUP(C27,Dados!$C$3:$C$329,Dados!$AA$3:'Dados'!$AA$329,"")} -> 11.178127 | AM27: {=_xlfn.XLOOKUP(C27,Dados!$C$3:$C$329,Dados!$AB$3:'Dados'!$AB$329,"")} -> 8.0800981 | AN27: {=_xlfn.XLOOKUP(C27,Dados!$C$3:$C$329,Dados!$AC$3:'Dados'!$AC$329,"")} -> 4.1731429 | AO27: {=_xlfn.XLOOKUP(C27,Dados!$C$3:$C$329,Dados!$AD$3:'Dados'!$AD$329,"")} -> 3.5762189
